Workbook

Sheet Scenarios
A1: Sumitomo Rubber Industries 51100 — Scenarios
A2: Pick a case in B4. Drivers growth + OPM rows follow the pick, so PL / BS / CF / Valuation all recompute. Columns B.. are each case's reference output; the last column is the live model for the picked case.
A4: Case (1=Bull / 2=Base / 3=Bear) | B4: 2 | C4: =CHOOSE($B$4,"Bull","Base","Bear")
B6: Bull | C6: Base | D6: Bear | E6: Picked → live model
A7: View (one line; the numbers are in the assumption table below) | B7: DUNLOP succeeds, oil settles -> business margin ~8% (still short of the 10% MTP) | C7: DUNLOP takes time, oil stays high, El Nino lifts rubber -> status quo, TP ~ current price | D7: DUNLOP fails + sector shock (oil $100, stronger El Nino) -> P/B 0.50 floor | E7: =CHOOSE($B$4,B7,C7,D7)
A8: FY26 OP (億) — live only | E8: =FS!V9
A9: FY27 Sales (億) — live only | E9: =FS!W4
A10: FY27 OP (億) | B10: 1022 | C10: 739 | D10: 510 | E10: =FS!W9
A11: FY27 OPM (%) | E11: =E10/E9*100
A12: FY27 EPS (¥) | B12: 240.3 | C12: 173.7 | D12: 119.8 | E12: =FS!W22
A13: FY27 BPS (¥) | B13: 3041 | C13: 3001 | D13: 2968 | E13: =FS!O45*100/FS!O21
A14: P/E applied (x) | B14: 9.69 | C14: 9.69 | E14: =N(CHOOSE($B$4,B14,C14,D14))
A15: P/B applied (x) | B15: 0.926 | C15: 0.774 | D15: 0.5 | E15: =N(CHOOSE($B$4,B15,C15,D15))
A16: Weight on P/E (0 = P/B only) | B16: 0.5 | C16: 0.5 | D16: 0 | E16: =N(CHOOSE($B$4,B16,C16,D16))
A17: Target price (¥) | B17: 2573 | C17: 2003 | D17: 1484 | E17: =IF(E16>0,E16*E12*E14+(1-E16)*E13*E15,E13*E15)
A18: vs price | B18: =IF(B19>0,B17/B19-1,"") | C18: =IF(C19>0,C17/C19-1,"") | D18: =IF(D19>0,D17/D19-1,"") | E18: =IF(E19>0,E17/E19-1,"")
A19: Price ref (¥) | B19: 2036 | C19: 2036 | D19: 2036 | E19: =N(CHOOSE($B$4,B19,C19,D19))
A22: Key assumptions per case (driver inputs)
B23: Bull | C23: Base | D23: Bear | E23: Picked
A24: TSR20 in 12M ($/kg, SGX curve x El Nino uplift) | B24: 2.61 | C24: 2.79 | D24: 2.97 | E24: =CHOOSE($B$4,B24,C24,D24)
A25: El Nino uplift multiple (measured = 1.0) | B25: 0.5 | C25: 1 | D25: 1.5 | E25: =CHOOSE($B$4,B25,C25,D25)
A26: Dubai ($/bbl, from Oct-2026) | B26: 80 | C26: 90 | D26: 100 | E26: =CHOOSE($B$4,B26,C26,D26)
A27: Price pass-through beta (history 0.90) | B27: 0.9 | C27: 0.7 | D27: 0.6 | E27: =CHOOSE($B$4,B27,C27,D27)
A28: Own-brand units YoY FY27 (%) | B28: 2.5 | C28: 1.5 | D28: 1 | E28: =CHOOSE($B$4,B28,C28,D28)
A29: Offtake FY26H2 vs plan (%) | B29: 100 | C29: 77 | D29: 70 | E29: =CHOOSE($B$4,B29,C29,D29)
A30: Offtake FY27 (10k units) | B30: 260 | C30: 240 | D30: 220 | E30: =CHOOSE($B$4,B30,C30,D30)
A31: SYNCHRO WEATHER FY27 (10k units) - placeholder | B31: 150 | C31: 130 | D31: 115 | E31: =CHOOSE($B$4,B31,C31,D31)
A32: Mix improvement (JPY 100m / Q) | B32: 30 | C32: 20 | D32: 10 | E32: =CHOOSE($B$4,B32,C32,D32)
A33: Excess inventory days at FY27 end (vs FY25 same Q) | B33: 3 | C33: 8 | D33: 20 | E33: =CHOOSE($B$4,B33,C33,D33)
A34: Common to all cases (FY27, JPY 100m): unrealized profit -58 / IEEPA refund drops out -40 / freight -20 / Project ARK +100 / expenses -130. The assumption table is for reference only - editing it does not recalc (rerun driver.py).
A37: Quarterly drivers per case — edit the case rows; the Selected rows feed Drivers
J38: FY26Q3 | K38: FY26Q4 | L38: FY27Q1 | M38: FY27Q2 | N38: FY27Q3 | O38: FY27Q4 | P38: FY28Q1 | Q38: FY28Q2
A39: Sales QoQ (%)
A40: 1. Bull | J40: 2.86 | K40: 17.39 | L40: -18.32 | M40: 6.63 | N40: 3.45 | O40: 16.35 | P40: -19.46 | Q40: 5.76
A41: 2. Base | J41: 2.25 | K41: 17.49 | L41: -19.04 | M41: 6.33 | N41: 3.42 | O41: 16.87 | P41: -19.63 | Q41: 5.86
A42: 3. Bear | J42: 2.06 | K42: 17.52 | L42: -19.6 | M42: 6.18 | N42: 3.43 | O42: 17.16 | P42: -19.48 | Q42: 5.95
A43: → Selected (feeds Drivers) | J43: =CHOOSE($B$4,J40,J41,J42) | K43: =CHOOSE($B$4,K40,K41,K42) | L43: =CHOOSE($B$4,L40,L41,L42) | M43: =CHOOSE($B$4,M40,M41,M42) | N43: =CHOOSE($B$4,N40,N41,N42) | O43: =CHOOSE($B$4,O40,O41,O42) | P43: =CHOOSE($B$4,P40,P41,P42) | Q43: =CHOOSE($B$4,Q40,Q41,Q42)
A45: Consolidated OPM (%)
A46: 1. Bull | J46: 4.25 | K46: 9.27 | L46: 2.42 | M46: 5.72 | N46: 7.52 | O46: 12.32 | P46: 5.05 | Q46: 7.15
A47: 2. Base | J47: 4.18 | K47: 9.24 | L47: 1.54 | M47: 3.39 | N47: 4.97 | O47: 10.36 | P47: 2.44 | Q47: 4.79
...

Sheet Drivers
A1: Sumitomo Rubber Industries 51100 — Drivers
A2: BLUE = input/actual; BLACK = same-sheet formula; GREEN = cross-sheet; YELLOW bg = forecast cell
A4: 1. Sales QoQ Growth (%) — ← Scenarios sheet (pick case 1/2/3 there; edit case rows there)
B5: FY24Q3 | C5: FY24Q4 | D5: FY25Q1 | E5: FY25Q2 | F5: FY25Q3 | G5: FY25Q4 | H5: FY26Q1 | I5: FY26Q2 | J5: FY26Q3 | K5: FY26Q4 | L5: FY27Q1 | M5: FY27Q2 | N5: FY27Q3 | O5: FY27Q4 | P5: FY28Q1 | Q5: FY28Q2 | T5: FY24 | U5: FY25 | V5: FY26 | W5: FY27 | X5: FY28
A6: Tires | J6: =Scenarios!J43 | K6: =Scenarios!K43 | L6: =Scenarios!L43 | M6: =Scenarios!M43 | N6: =Scenarios!N43 | O6: =Scenarios!O43 | P6: =Scenarios!P43 | Q6: =Scenarios!Q43
A7: Sports | J7: =Scenarios!J43 | K7: =Scenarios!K43 | L7: =Scenarios!L43 | M7: =Scenarios!M43 | N7: =Scenarios!N43 | O7: =Scenarios!O43 | P7: =Scenarios!P43 | Q7: =Scenarios!Q43
A8: IndustrialAndOtherProducts | J8: =Scenarios!J43 | K8: =Scenarios!K43 | L8: =Scenarios!L43 | M8: =Scenarios!M43 | N8: =Scenarios!N43 | O8: =Scenarios!O43 | P8: =Scenarios!P43 | Q8: =Scenarios!Q43
A10: Consolidated OPM (%) — ← Scenarios sheet selected case (OP = Sales × OPM) | J10: =Scenarios!J49 | K10: =Scenarios!K49 | L10: =Scenarios!L49 | M10: =Scenarios!M49 | N10: =Scenarios!N49 | O10: =Scenarios!O49 | P10: =Scenarios!P49 | Q10: =Scenarios!Q49
A12: 2. Sales by Segment (億円) — historical actuals from deck
B13: FY24Q3 | C13: FY24Q4 | D13: FY25Q1 | E13: FY25Q2 | F13: FY25Q3 | G13: FY25Q4 | H13: FY26Q1 | I13: FY26Q2 | T13: FY24 | U13: FY25 | V13: FY26
A14: Tires | C14: 10463.94 | G14: 10436.83 | T14: =IF(COUNT(B14:C14)=0,"",SUM(B14:C14)) | U14: =IF(COUNT(D14:G14)=0,"",SUM(D14:G14)) | V14: =IF(COUNT(H14:K14)=0,"",SUM(H14:K14)) | W14: =IF(COUNT(L14:O14)=0,"",SUM(L14:O14)) | X14: =IF(COUNT(P14:Q14)=0,"",SUM(P14:Q14))
A15: Sports | C15: 1256.5 | G15: 1255.74 | T15: =IF(COUNT(B15:C15)=0,"",SUM(B15:C15)) | U15: =IF(COUNT(D15:G15)=0,"",SUM(D15:G15)) | V15: =IF(COUNT(H15:K15)=0,"",SUM(H15:K15)) | W15: =IF(COUNT(L15:O15)=0,"",SUM(L15:O15)) | X15: =IF(COUNT(P15:Q15)=0,"",SUM(P15:Q15))
A16: IndustrialAndOtherProducts | C16: 398.12 | G16: 378.04 | T16: =IF(COUNT(B16:C16)=0,"",SUM(B16:C16)) | U16: =IF(COUNT(D16:G16)=0,"",SUM(D16:G16)) | V16: =IF(COUNT(H16:K16)=0,"",SUM(H16:K16)) | W16: =IF(COUNT(L16:O16)=0,"",SUM(L16:O16)) | X16: =IF(COUNT(P16:Q16)=0,"",SUM(P16:Q16))
A17: TOTAL | B17: =SUM(B14:B16) | C17: =SUM(C14:C16) | D17: =SUM(D14:D16) | E17: =SUM(E14:E16) | F17: =SUM(F14:F16) | G17: =SUM(G14:G16) | H17: =SUM(H14:H16) | I17: =SUM(I14:I16) | T17: =IF(COUNT(B17:C17)=0,"",SUM(B17:C17)) | U17: =IF(COUNT(D17:G17)=0,"",SUM(D17:G17)) | V17: =IF(COUNT(H17:K17)=0,"",SUM(H17:K17)) | W17: =IF(COUNT(L17:O17)=0,"",SUM(L17:O17)) | X17: =IF(COUNT(P17:Q17)=0,"",SUM(P17:Q17))
A19: ↳ Segment OP (factbook 営業利益, 億)
A20: Tires OP | T20: =IF(COUNT(B20:C20)=0,"",SUM(B20:C20)) | U20: =IF(COUNT(D20:G20)=0,"",SUM(D20:G20)) | V20: =IF(COUNT(H20:K20)=0,"",SUM(H20:K20)) | W20: =IF(COUNT(L20:O20)=0,"",SUM(L20:O20)) | X20: =IF(COUNT(P20:Q20)=0,"",SUM(P20:Q20))
A21: Sports OP | T21: =IF(COUNT(B21:C21)=0,"",SUM(B21:C21)) | U21: =IF(COUNT(D21:G21)=0,"",SUM(D21:G21)) | V21: =IF(COUNT(H21:K21)=0,"",SUM(H21:K21)) | W21: =IF(COUNT(L21:O21)=0,"",SUM(L21:O21)) | X21: =IF(COUNT(P21:Q21)=0,"",SUM(P21:Q21))
A22: IndustrialAndOtherProducts OP | T22: =IF(COUNT(B22:C22)=0,"",SUM(B22:C22)) | U22: =IF(COUNT(D22:G22)=0,"",SUM(D22:G22)) | V22: =IF(COUNT(H22:K22)=0,"",SUM(H22:K22)) | W22: =IF(COUNT(L22:O22)=0,"",SUM(L22:O22)) | X22: =IF(COUNT(P22:Q22)=0,"",SUM(P22:Q22))
A23: OP TOTAL (= consolidated) | B23: =SUM(B20:B22) | C23: =SUM(C20:C22) | D23: =SUM(D20:D22) | E23: =SUM(E20:E22) | F23: =SUM(F20:F22) | G23: =SUM(G20:G22) | H23: =SUM(H20:H22) | I23: =SUM(I20:I22) | T23: =IF(COUNT(B23:C23)=0,"",SUM(B23:C23)) | U23: =IF(COUNT(D23:G23)=0,"",SUM(D23:G23)) | V23: =IF(COUNT(H23:K23)=0,"",SUM(H23:K23)) | W23: =IF(COUNT(L23:O23)=0,"",SUM(L23:O23)) | X23: =IF(COUNT(P23:Q23)=0,"",SUM(P23:Q23))
A25: 4. Sales by Region (億円)
B26: FY24Q3 | C26: FY24Q4 | D26: FY25Q1 | E26: FY25Q2 | F26: FY25Q3 | G26: FY25Q4 | H26: FY26Q1 | I26: FY26Q2 | T26: FY24 | U26: FY25 | V26: FY26
A27: 日本 | T27: =IF(COUNT(B27:C27)=0,"",SUM(B27:C27)) | U27: =IF(COUNT(D27:G27)=0,"",SUM(D27:G27)) | V27: =IF(COUNT(H27:K27)=0,"",SUM(H27:K27)) | W27: =IF(COUNT(L27:O27)=0,"",SUM(L27:O27)) | X27: =IF(COUNT(P27:Q27)=0,"",SUM(P27:Q27))
A28: 北米 | T28: =IF(COUNT(B28:C28)=0,"",SUM(B28:C28)) | U28: =IF(COUNT(D28:G28)=0,"",SUM(D28:G28)) | V28: =IF(COUNT(H28:K28)=0,"",SUM(H28:K28)) | W28: =IF(COUNT(L28:O28)=0,"",SUM(L28:O28)) | X28: =IF(COUNT(P28:Q28)=0,"",SUM(P28:Q28))
A29: 欧州 | T29: =IF(COUNT(B29:C29)=0,"",SUM(B29:C29)) | U29: =IF(COUNT(D29:G29)=0,"",SUM(D29:G29)) | V29: =IF(COUNT(H29:K29)=0,"",SUM(H29:K29)) | W29: =IF(COUNT(L29:O29)=0,"",SUM(L29:O29)) | X29: =IF(COUNT(P29:Q29)=0,"",SUM(P29:Q29))
A30: アジア | T30: =IF(COUNT(B30:C30)=0,"",SUM(B30:C30)) | U30: =IF(COUNT(D30:G30)=0,"",SUM(D30:G30)) | V30: =IF(COUNT(H30:K30)=0,"",SUM(H30:K30)) | W30: =IF(COUNT(L30:O30)=0,"",SUM(L30:O30)) | X30: =IF(COUNT(P30:Q30)=0,"",SUM(P30:Q30))
A31: その他 | T31: =IF(COUNT(B31:C31)=0,"",SUM(B31:C31)) | U31: =IF(COUNT(D31:G31)=0,"",SUM(D31:G31)) | V31: =IF(COUNT(H31:K31)=0,"",SUM(H31:K31)) | W31: =IF(COUNT(L31:O31)=0,"",SUM(L31:O31)) | X31: =IF(COUNT(P31:Q31)=0,"",SUM(P31:Q31))
A32: TOTAL | B32: =SUM(B27:B31) | C32: =SUM(C27:C31) | D32: =SUM(D27:D31) | E32: =SUM(E27:E31) | F32: =SUM(F27:F31) | G32: =SUM(G27:G31) | H32: =SUM(H27:H31) | I32: =SUM(I27:I31) | T32: =IF(COUNT(B32:C32)=0,"",SUM(B32:C32)) | U32: =IF(COUNT(D32:G32)=0,"",SUM(D32:G32)) | V32: =IF(COUNT(H32:K32)=0,"",SUM(H32:K32)) | W32: =IF(COUNT(L32:O32)=0,"",SUM(L32:O32)) | X32: =IF(COUNT(P32:Q32)=0,"",SUM(P32:Q32))
A35: 6. Margin Assumptions (OP = Sales × per-Q consolidated OPM)
A36: Per-Segment GPM (reference)
A37: Segment | B37: GPM
A38: Tires | B38: 0.31
A39: Sports | B39: 0.28
A40: IndustrialAndOtherProducts | B40: 0.26
A42: Consolidated SG&A / Sales | B42: 0.24

Sheet FS
A1: P&L (億円, EPS in JPY) — BLUE=actual/input, BLACK=formula, GREEN=cross-sheet, ORANGE=guide
A3: Line Item | B3: FY24Q3 | C3: FY24Q4 | D3: FY25Q1 | E3: FY25Q2 | F3: FY25Q3 | G3: FY25Q4 | H3: FY26Q1 | I3: FY26Q2 | J3: FY26Q3 | K3: FY26Q4 | L3: FY27Q1 | M3: FY27Q2 | N3: FY27Q3 | O3: FY27Q4 | P3: FY28Q1 | Q3: FY28Q2 | T3: FY24 | U3: FY25 | V3: FY26 | W3: FY27 | X3: FY28 | Y3: FY26 GUIDE | Z3: Model vs Guide | AA3: Forecast Formula (plain English)
A4: Sales | B4: 2879 | C4: 3369.1 | D4: 2877.8 | E4: 2844.1 | F4: 2894.2 | G4: 3454.5 | H4: 3021.7 | I4: 3176.3 | J4: =I4*(1+AVERAGE(Drivers!J6:Drivers!J8)/100) | K4: =J4*(1+AVERAGE(Drivers!K6:Drivers!K8)/100) | L4: =K4*(1+AVERAGE(Drivers!L6:Drivers!L8)/100) | M4: =L4*(1+AVERAGE(Drivers!M6:Drivers!M8)/100) | N4: =M4*(1+AVERAGE(Drivers!N6:Drivers!N8)/100) | O4: =N4*(1+AVERAGE(Drivers!O6:Drivers!O8)/100) | P4: =O4*(1+AVERAGE(Drivers!P6:Drivers!P8)/100) | Q4: =P4*(1+AVERAGE(Drivers!Q6:Drivers!Q8)/100) | T4: =IF(COUNTBLANK(B4:C4)>0,"",SUM(B4:C4)) | U4: =IF(COUNTBLANK(D4:G4)>0,"",SUM(D4:G4)) | V4: =IF(COUNTBLANK(H4:K4)>0,"",SUM(H4:K4)) | W4: =IF(COUNTBLANK(L4:O4)>0,"",SUM(L4:O4)) | X4: =IF(COUNTBLANK(P4:Q4)>0,"",SUM(P4:Q4)) | Y4: 13300 | Z4: =(J4+K4+L4+M4)/Y4-1 | AA4: prior Sales × QoQ growth (mean of cfg.order_growth_qoq across segments)
A5: COGS | B5: =B4-B6 | C5: =C4-C6 | D5: =D4-D6 | E5: =E4-E6 | F5: =F4-F6 | G5: =G4-G6 | H5: =H4-H6 | I5: =I4-I6 | ... Q5: =Q4-Q6 | T5: =IF(COUNTBLANK(B5:C5)>0,"",SUM(B5:C5)) | U5: =IF(COUNTBLANK(D5:G5)>0,"",SUM(D5:G5)) | V5: =IF(COUNTBLANK(H5:K5)>0,"",SUM(H5:K5)) | W5: =IF(COUNTBLANK(L5:O5)>0,"",SUM(L5:O5)) | X5: =IF(COUNTBLANK(P5:Q5)>0,"",SUM(P5:Q5)) | AA5: Sales − Gross Profit
A6: Gross Profit | B6: 833.3 | C6: 982 | D6: 836.8 | E6: 825.5 | F6: 864.3 | G6: 1157 | H6: 936.3 | I6: 1005.6 | J6: =J9+J8 | K6: =K9+K8 | L6: =L9+L8 | M6: =M9+M8 | N6: =N9+N8 | O6: =O9+O8 | P6: =P9+P8 | Q6: =Q9+Q8 | T6: =IF(COUNTBLANK(B6:C6)>0,"",SUM(B6:C6)) | U6: =IF(COUNTBLANK(D6:G6)>0,"",SUM(D6:G6)) | V6: =IF(COUNTBLANK(H6:K6)>0,"",SUM(H6:K6)) | W6: =IF(COUNTBLANK(L6:O6)>0,"",SUM(L6:O6)) | X6: =IF(COUNTBLANK(P6:Q6)>0,"",SUM(P6:Q6)) | AA6: OP + SG&A (OPM-driven: GP is derived, not an input)
A7: GPM % | B7: =B6/B4*100 | C7: =C6/C4*100 | D7: =D6/D4*100 | E7: =E6/E4*100 | F7: =F6/F4*100 | G7: =G6/G4*100 | H7: =H6/H4*100 | I7: =I6/I4*100 | ... Q7: =Q6/Q4*100 | T7: =IF(OR(COUNTBLANK(B6:C6)>0,COUNTBLANK(B4:C4)>0),"",SUM(B6:C6)/SUM(B4:C4)*100) | U7: =IF(OR(COUNTBLANK(D6:G6)>0,COUNTBLANK(D4:G4)>0),"",SUM(D6:G6)/SUM(D4:G4)*100) | V7: =IF(OR(COUNTBLANK(H6:K6)>0,COUNTBLANK(H4:K4)>0),"",SUM(H6:K6)/SUM(H4:K4)*100) | W7: =IF(OR(COUNTBLANK(L6:O6)>0,COUNTBLANK(L4:O4)>0),"",SUM(L6:O6)/SUM(L4:O4)*100) | X7: =IF(OR(COUNTBLANK(P6:Q6)>0,COUNTBLANK(P4:Q4)>0),"",SUM(P6:Q6)/SUM(P4:Q4)*100) | AA7: Gross Profit ÷ Sales
A8: SG&A | B8: =B6-B9 | C8: =C6-C9 | D8: =D6-D9 | E8: =E6-E9 | F8: =F6-F9 | G8: =G6-G9 | H8: =H6-H9 | I8: =I6-I9 | J8: =J4*0.24 | K8: =K4*0.24 | L8: =L4*0.24 | M8: =M4*0.24 | N8: =N4*0.24 | O8: =O4*0.24 | P8: =P4*0.24 | Q8: =Q4*0.24 | T8: =IF(COUNTBLANK(B8:C8)>0,"",SUM(B8:C8)) | U8: =IF(COUNTBLANK(D8:G8)>0,"",SUM(D8:G8)) | V8: =IF(COUNTBLANK(H8:K8)>0,"",SUM(H8:K8)) | W8: =IF(COUNTBLANK(L8:O8)>0,"",SUM(L8:O8)) | X8: =IF(COUNTBLANK(P8:Q8)>0,"",SUM(P8:Q8)) | AA8: Sales × 24.0% (yaml override (recent run-rate))
A9: Operating Profit | B9: -304.7 | C9: -3 | D9: 123.2 | E9: 147.2 | F9: 191 | G9: 364.5 | H9: 150.7 | I9: 230.8 | J9: =J4*Drivers!J10/100 | K9: =K4*Drivers!K10/100 | L9: =L4*Drivers!L10/100 | M9: =M4*Drivers!M10/100 | N9: =N4*Drivers!N10/100 | O9: =O4*Drivers!O10/100 | P9: =P4*Drivers!P10/100 | Q9: =Q4*Drivers!Q10/100 | T9: =IF(COUNTBLANK(B9:C9)>0,"",SUM(B9:C9)) | U9: =IF(COUNTBLANK(D9:G9)>0,"",SUM(D9:G9)) | V9: =IF(COUNTBLANK(H9:K9)>0,"",SUM(H9:K9)) | W9: =IF(COUNTBLANK(L9:O9)>0,"",SUM(L9:O9)) | X9: =IF(COUNTBLANK(P9:Q9)>0,"",SUM(P9:Q9)) | Y9: 890 | Z9: =(J9+K9+L9+M9)/Y9-1 | AA9: Sales × per-Q consolidated OPM (Drivers)
A10: OPM % | B10: =B9/B4*100 | C10: =C9/C4*100 | D10: =D9/D4*100 | E10: =E9/E4*100 | F10: =F9/F4*100 | G10: =G9/G4*100 | H10: =H9/H4*100 | I10: =I9/I4*100 | ... Q10: =Q9/Q4*100 | T10: =IF(OR(COUNTBLANK(B9:C9)>0,COUNTBLANK(B4:C4)>0),"",SUM(B9:C9)/SUM(B4:C4)*100) | U10: =IF(OR(COUNTBLANK(D9:G9)>0,COUNTBLANK(D4:G4)>0),"",SUM(D9:G9)/SUM(D4:G4)*100) | V10: =IF(OR(COUNTBLANK(H9:K9)>0,COUNTBLANK(H4:K4)>0),"",SUM(H9:K9)/SUM(H4:K4)*100) | W10: =IF(OR(COUNTBLANK(L9:O9)>0,COUNTBLANK(L4:O4)>0),"",SUM(L9:O9)/SUM(L4:O4)*100) | X10: =IF(OR(COUNTBLANK(P9:Q9)>0,COUNTBLANK(P4:Q4)>0),"",SUM(P9:Q9)/SUM(P4:Q4)*100) | Y10: 6.7 | Z10: =(J9+K9+L9+M9)/(J4+K4+L4+M4)*100-Y10 | AA10: OP ÷ Sales
A11: ± Non-Op / 特別 (net) | B11: =B12-B9 | C11: =C12-C9 | D11: =D12-D9 | E11: =E12-E9 | F11: =F12-F9 | G11: =G12-G9 | H11: =H12-H9 | I11: =I12-I9 | J11: =J9*FS!$B$86/100 | K11: =K9*FS!$B$86/100 | L11: =L9*FS!$B$86/100 | M11: =M9*FS!$B$86/100 | N11: =N9*FS!$B$86/100 | O11: =O9*FS!$B$86/100 | P11: =P9*FS!$B$86/100 | Q11: =Q9*FS!$B$86/100 | T11: =IF(COUNTBLANK(B11:C11)>0,"",SUM(B11:C11)) | U11: =IF(COUNTBLANK(D11:G11)>0,"",SUM(D11:G11)) | V11: =IF(COUNTBLANK(H11:K11)>0,"",SUM(H11:K11)) | W11: =IF(COUNTBLANK(L11:O11)>0,"",SUM(L11:O11)) | X11: =IF(COUNTBLANK(P11:Q11)>0,"",SUM(P11:Q11)) | AA11: Hist: Pretax−OP (実際 金融/持分法/特別); Fcst: OP × -4.3%
A12: Pretax Profit (税前) | B12: -459.1 | C12: 85.7 | D12: 39.6 | E12: 161.2 | F12: 204 | G12: 373.2 | H12: 146.7 | I12: 230.8 | J12: =J9+J11 | K12: =K9+K11 | L12: =L9+L11 | M12: =M9+M11 | N12: =N9+N11 | O12: =O9+O11 | P12: =P9+P11 | Q12: =Q9+Q11 | T12: =IF(COUNTBLANK(B12:C12)>0,"",SUM(B12:C12)) | U12: =IF(COUNTBLANK(D12:G12)>0,"",SUM(D12:G12)) | V12: =IF(COUNTBLANK(H12:K12)>0,"",SUM(H12:K12)) | W12: =IF(COUNTBLANK(L12:O12)>0,"",SUM(L12:O12)) | X12: =IF(COUNTBLANK(P12:Q12)>0,"",SUM(P12:Q12)) | AA12: Pretax (税前): Hist=disclosed actual; Fcst=OP + Non-Op
A13: Pretax M % | B13: =B12/B4*100 | C13: =C12/C4*100 | D13: =D12/D4*100 | E13: =E12/E4*100 | F13: =F12/F4*100 | G13: =G12/G4*100 | H13: =H12/H4*100 | I13: =I12/I4*100 | ... Q13: =Q12/Q4*100 | T13: =IF(OR(COUNTBLANK(B12:C12)>0,COUNTBLANK(B4:C4)>0),"",SUM(B12:C12)/SUM(B4:C4)*100) | U13: =IF(OR(COUNTBLANK(D12:G12)>0,COUNTBLANK(D4:G4)>0),"",SUM(D12:G12)/SUM(D4:G4)*100) | V13: =IF(OR(COUNTBLANK(H12:K12)>0,COUNTBLANK(H4:K4)>0),"",SUM(H12:K12)/SUM(H4:K4)*100) | W13: =IF(OR(COUNTBLANK(L12:O12)>0,COUNTBLANK(L4:O4)>0),"",SUM(L12:O12)/SUM(L4:O4)*100) | X13: =IF(OR(COUNTBLANK(P12:Q12)>0,COUNTBLANK(P4:Q4)>0),"",SUM(P12:Q12)/SUM(P4:Q4)*100) | AA13: Pretax ÷ Sales
A14: − Income Tax | B14: -114.2 | C14: 22.8 | D14: 7.7 | E14: 36.5 | F14: 77.7 | G14: 129 | H14: 51 | I14: 50.2 | J14: =J12*FS!$B$85/100 | K14: =K12*FS!$B$85/100 | L14: =L12*FS!$B$85/100 | M14: =M12*FS!$B$85/100 | N14: =N12*FS!$B$85/100 | O14: =O12*FS!$B$85/100 | P14: =P12*FS!$B$85/100 | Q14: =Q12*FS!$B$85/100 | T14: =IF(COUNTBLANK(B14:C14)>0,"",SUM(B14:C14)) | U14: =IF(COUNTBLANK(D14:G14)>0,"",SUM(D14:G14)) | V14: =IF(COUNTBLANK(H14:K14)>0,"",SUM(H14:K14)) | W14: =IF(COUNTBLANK(L14:O14)>0,"",SUM(L14:O14)) | X14: =IF(COUNTBLANK(P14:Q14)>0,"",SUM(P14:Q14)) | AA14: Hist: actual 法人税等; Fcst: Pretax × 31.2% (auto)
A15: Tax rate % | B15: =IF(B12=0,"",B14/B12*100) | C15: =IF(C12=0,"",C14/C12*100) | D15: =IF(D12=0,"",D14/D12*100) | E15: =IF(E12=0,"",E14/E12*100) | F15: =IF(F12=0,"",F14/F12*100) | G15: =IF(G12=0,"",G14/G12*100) | H15: =IF(H12=0,"",H14/H12*100) | I15: =IF(I12=0,"",I14/I12*100) | J15: =FS!$B$85 | K15: =FS!$B$85 | L15: =FS!$B$85 | M15: =FS!$B$85 | N15: =FS!$B$85 | O15: =FS!$B$85 | P15: =FS!$B$85 | Q15: =FS!$B$85 | T15: =IF(OR(COUNTBLANK(B14:C14)>0,COUNTBLANK(B12:C12)>0),"",SUM(B14:C14)/SUM(B12:C12)*100) | U15: =IF(OR(COUNTBLANK(D14:G14)>0,COUNTBLANK(D12:G12)>0),"",SUM(D14:G14)/SUM(D12:G12)*100) | V15: =IF(OR(COUNTBLANK(H14:K14)>0,COUNTBLANK(H12:K12)>0),"",SUM(H14:K14)/SUM(H12:K12)*100) | W15: =IF(OR(COUNTBLANK(L14:O14)>0,COUNTBLANK(L12:O12)>0),"",SUM(L14:O14)/SUM(L12:O12)*100) | X15: =IF(OR(COUNTBLANK(P14:Q14)>0,COUNTBLANK(P12:Q12)>0),"",SUM(P14:Q14)/SUM(P12:Q12)*100) | AA15: Hist: Income Tax ÷ Pretax (実効税率); Fcst: flat 31.2% assumption (Summary)
A16: − Minority Int. (NCI) | B16: =B12-B14-B18 | C16: =C12-C14-C18 | D16: =D12-D14-D18 | E16: =E12-E14-E18 | F16: =F12-F14-F18 | G16: =G12-G14-G18 | H16: =H12-H14-H18 | I16: =I12-I14-I18 | J16: =J12*FS!$B$101/100 | K16: =K12*FS!$B$101/100 | L16: =L12*FS!$B$101/100 | M16: =M12*FS!$B$101/100 | N16: =N12*FS!$B$101/100 | O16: =O12*FS!$B$101/100 | P16: =P12*FS!$B$101/100 | Q16: =Q12*FS!$B$101/100 | T16: =IF(COUNTBLANK(B16:C16)>0,"",SUM(B16:C16)) | U16: =IF(COUNTBLANK(D16:G16)>0,"",SUM(D16:G16)) | V16: =IF(COUNTBLANK(H16:K16)>0,"",SUM(H16:K16)) | W16: =IF(COUNTBLANK(L16:O16)>0,"",SUM(L16:O16)) | X16: =IF(COUNTBLANK(P16:Q16)>0,"",SUM(P16:Q16)) | AA16: Hist: Pretax−Tax−NP; Fcst: Pretax × 3.7%
A18: Net Income | B18: -346.8 | C18: 58.2 | D18: 35.6 | E18: 108.1 | F18: 116.4 | G18: 243.7 | H18: 85.6 | I18: 173 | J18: =J12-J14-J16 | K18: =K12-K14-K16 | L18: =L12-L14-L16 | M18: =M12-M14-M16 | N18: =N12-N14-N16 | O18: =O12-O14-O16 | P18: =P12-P14-P16 | Q18: =Q12-Q14-Q16 | T18: =IF(COUNTBLANK(B18:C18)>0,"",SUM(B18:C18)) | U18: =IF(COUNTBLANK(D18:G18)>0,"",SUM(D18:G18)) | V18: =IF(COUNTBLANK(H18:K18)>0,"",SUM(H18:K18)) | W18: =IF(COUNTBLANK(L18:O18)>0,"",SUM(L18:O18)) | X18: =IF(COUNTBLANK(P18:Q18)>0,"",SUM(P18:Q18)) | Y18: 550 | Z18: =(J18+K18+L18+M18)/Y18-1 | AA18: Pretax − Tax − Minority (親会社株主帰属)
A19: NPM % | B19: =B18/B4*100 | C19: =C18/C4*100 | D19: =D18/D4*100 | E19: =E18/E4*100 | F19: =F18/F4*100 | G19: =G18/G4*100 | H19: =H18/H4*100 | I19: =I18/I4*100 | ... Q19: =Q18/Q4*100 | T19: =IF(OR(COUNTBLANK(B18:C18)>0,COUNTBLANK(B4:C4)>0),"",SUM(B18:C18)/SUM(B4:C4)*100) | U19: =IF(OR(COUNTBLANK(D18:G18)>0,COUNTBLANK(D4:G4)>0),"",SUM(D18:G18)/SUM(D4:G4)*100) | V19: =IF(OR(COUNTBLANK(H18:K18)>0,COUNTBLANK(H4:K4)>0),"",SUM(H18:K18)/SUM(H4:K4)*100) | W19: =IF(OR(COUNTBLANK(L18:O18)>0,COUNTBLANK(L4:O4)>0),"",SUM(L18:O18)/SUM(L4:O4)*100) | X19: =IF(OR(COUNTBLANK(P18:Q18)>0,COUNTBLANK(P4:Q4)>0),"",SUM(P18:Q18)/SUM(P4:Q4)*100) | AA19: NP ÷ Sales
A21: Diluted Shares (M) | B21: 263 | C21: 263 | D21: 263 | E21: 263 | F21: 262.9 | G21: 262.9 | H21: 262.8 | I21: 262.8 | J21: =I21-FS!J76*100/FS!$B$99 | K21: =J21-FS!K76*100/FS!$B$99 | L21: =K21-FS!L76*100/FS!$B$99 | M21: =L21-FS!M76*100/FS!$B$99 | N21: =M21-FS!N76*100/FS!$B$99 | O21: =N21-FS!O76*100/FS!$B$99 | P21: =O21-FS!P76*100/FS!$B$99 | Q21: =P21-FS!Q76*100/FS!$B$99 | T21: =IF(ISBLANK(C21),"",C21) | U21: =IF(ISBLANK(G21),"",G21) | V21: =IF(ISBLANK(K21),"",K21) | W21: =IF(ISBLANK(O21),"",O21) | X21: =IF(ISBLANK(Q21),"",Q21) | AA21: Hist: per-Q AvgSh from fins_summary; Fcst: prior − Buyback×100÷AvgPx (B26)
A22: EPS (¥) | B22: =B18*100/B21 | C22: =C18*100/C21 | D22: =D18*100/D21 | E22: =E18*100/E21 | F22: =F18*100/F21 | G22: =G18*100/G21 | H22: =H18*100/H21 | I22: =I18*100/I21 | ... Q22: =Q18*100/Q21 | T22: =IF(COUNTBLANK(B22:C22)>0,"",SUM(B22:C22)) | U22: =IF(COUNTBLANK(D22:G22)>0,"",SUM(D22:G22)) | V22: =IF(COUNTBLANK(H22:K22)>0,"",SUM(H22:K22)) | W22: =IF(COUNTBLANK(L22:O22)>0,"",SUM(L22:O22)) | X22: =IF(COUNTBLANK(P22:Q22)>0,"",SUM(P22:Q22)) | Y22: 209.25 | Z22: =(J22+K22+L22+M22)/Y22-1 | AA22: NP × 100 ÷ Shares (oku → yen)
A23: DPS (¥) | B23: =B22*0.4 | C23: =C22*0.4 | D23: =D22*0.4 | E23: =E22*0.4 | F23: =F22*0.4 | G23: =G22*0.4 | H23: =H22*0.4 | I23: =I22*0.4 | J23: =J22*FS!$B$88/100 | K23: =K22*FS!$B$88/100 | L23: =L22*FS!$B$88/100 | M23: =M22*FS!$B$88/100 | N23: =N22*FS!$B$88/100 | O23: =O22*FS!$B$88/100 | P23: =P22*FS!$B$88/100 | Q23: =Q22*FS!$B$88/100 | T23: =IF(COUNTBLANK(B23:C23)>0,"",SUM(B23:C23)) | U23: =IF(COUNTBLANK(D23:G23)>0,"",SUM(D23:G23)) | V23: =IF(COUNTBLANK(H23:K23)>0,"",SUM(H23:K23)) | W23: =IF(COUNTBLANK(L23:O23)>0,"",SUM(L23:O23)) | X23: =IF(COUNTBLANK(P23:Q23)>0,"",SUM(P23:Q23)) | AA23: Disclosed DPS (実績/会社予想): interim@Q2, year-end@Q4; else EPS×payout
A24: Payout % | B24: =IF(B22=0,"",B23/B22*100) | C24: =IF(C22=0,"",C23/C22*100) | D24: =IF(D22=0,"",D23/D22*100) | E24: =IF(E22=0,"",E23/E22*100) | F24: =IF(F22=0,"",F23/F22*100) | G24: =IF(G22=0,"",G23/G22*100) | H24: =IF(H22=0,"",H23/H22*100) | I24: =IF(I22=0,"",I23/I22*100) | ... Q24: =IF(Q22=0,"",Q23/Q22*100) | T24: =IF(OR(COUNTBLANK(B23:C23)>0,COUNTBLANK(B22:C22)>0),"",SUM(B23:C23)/SUM(B22:C22)*100) | U24: =IF(OR(COUNTBLANK(D23:G23)>0,COUNTBLANK(D22:G22)>0),"",SUM(D23:G23)/SUM(D22:G22)*100) | V24: =IF(OR(COUNTBLANK(H23:K23)>0,COUNTBLANK(H22:K22)>0),"",SUM(H23:K23)/SUM(H22:K22)*100) | W24: =IF(OR(COUNTBLANK(L23:O23)>0,COUNTBLANK(L22:O22)>0),"",SUM(L23:O23)/SUM(L22:O22)*100) | X24: =IF(OR(COUNTBLANK(P23:Q23)>0,COUNTBLANK(P22:Q22)>0),"",SUM(P23:Q23)/SUM(P22:Q22)*100) | AA24: DPS ÷ EPS
A27: Balance Sheet (億) — BLUE=actual/input, BLACK=formula, GREEN=cross-sheet, ORANGE=guide/end-of-FY
A29: Line Item | B29: FY24Q3 | C29: FY24Q4 | D29: FY25Q1 | E29: FY25Q2 | F29: FY25Q3 | G29: FY25Q4 | H29: FY26Q1 | I29: FY26Q2 | J29: FY26Q3 | K29: FY26Q4 | L29: FY27Q1 | M29: FY27Q2 | N29: FY27Q3 | O29: FY27Q4 | P29: FY28Q1 | Q29: FY28Q2 | T29: FY24 | U29: FY25 | V29: FY26 | W29: FY27 | X29: FY28 | Y29: FY26 EoFY | AA29: Forecast Formula (plain English)
A30: Cash & Equivalents | B30: 699.4 | C30: 1003.8 | D30: 870.4 | E30: 859.8 | F30: 1020.8 | G30: 986.4 | H30: 993.4 | I30: 986.9 | J30: =I30+FS!J63+FS!J64+FS!J65 | K30: =J30+FS!K63+FS!K64+FS!K65 | L30: =K30+FS!L63+FS!L64+FS!L65 | M30: =L30+FS!M63+FS!M64+FS!M65 | N30: =M30+FS!N63+FS!N64+FS!N65 | O30: =N30+FS!O63+FS!O64+FS!O65 | P30: =O30+FS!P63+FS!P64+FS!P65 | Q30: =P30+FS!Q63+FS!Q64+FS!Q65 | T30: =IF(ISBLANK(C30),"",C30) | U30: =IF(ISBLANK(G30),"",G30) | V30: =IF(ISBLANK(K30),"",K30) | W30: =IF(ISBLANK(O30),"",O30) | X30: =IF(ISBLANK(Q30),"",Q30) | Y30: =Q30 | AA30: Prior Cash + OCF + ICF + Financing CF (rolled from CF sheet; NOT Free CF — that is the separate OCF+ICF row)
A31: Trade Receivables | B31: 1944.3 | C31: 2216.8 | D31: 2079.1 | E31: 1864.6 | F31: 1945.9 | G31: 2093.2 | H31: 2160.7 | I31: 2072.8 | J31: =J55*FS!J4/91 | K31: =K55*FS!K4/91 | L31: =L55*FS!L4/91 | M31: =M55*FS!M4/91 | N31: =N55*FS!N4/91 | O31: =O55*FS!O4/91 | P31: =P55*FS!P4/91 | Q31: =Q55*FS!Q4/91 | T31: =IF(ISBLANK(C31),"",C31) | U31: =IF(ISBLANK(G31),"",G31) | V31: =IF(ISBLANK(K31),"",K31) | W31: =IF(ISBLANK(O31),"",O31) | X31: =IF(ISBLANK(Q31),"",Q31) | AA31: Sales × DSO / 91 (or actual when available)
A32: Inventory | B32: 2959.6 | C32: 2909.5 | D32: 2826.2 | E32: 2899.6 | F32: 3075.7 | G32: 2981.2 | H32: 3155.6 | I32: 3494.7 | J32: =J56*FS!J5/91 | K32: =K56*FS!K5/91 | L32: =L56*FS!L5/91 | M32: =M56*FS!M5/91 | N32: =N56*FS!N5/91 | O32: =O56*FS!O5/91 | P32: =P56*FS!P5/91 | Q32: =Q56*FS!Q5/91 | T32: =IF(ISBLANK(C32),"",C32) | U32: =IF(ISBLANK(G32),"",G32) | V32: =IF(ISBLANK(K32),"",K32) | W32: =IF(ISBLANK(O32),"",O32) | X32: =IF(ISBLANK(Q32),"",Q32) | AA32: COGS × DIO / 91
A33: Other CA | B33: 781.4 | C33: 567.5 | D33: 571.8 | E33: 681.5 | F33: 777.6 | G33: 732.4 | H33: 699.4 | I33: 626.4 | J33: =I33 | K33: =J33 | L33: =K33 | M33: =L33 | N33: =M33 | O33: =N33 | P33: =O33 | Q33: =P33 | T33: =IF(ISBLANK(C33),"",C33) | U33: =IF(ISBLANK(G33),"",G33) | V33: =IF(ISBLANK(K33),"",K33) | W33: =IF(ISBLANK(O33),"",O33) | X33: =IF(ISBLANK(Q33),"",Q33) | AA33: Held constant from prior (roll-forward, NOT zeroed)
A34: Current Assets | B34: =B30+B31+B32+B33 | C34: =C30+C31+C32+C33 | D34: =D30+D31+D32+D33 | E34: =E30+E31+E32+E33 | F34: =F30+F31+F32+F33 | G34: =G30+G31+G32+G33 | H34: =H30+H31+H32+H33 | I34: =I30+I31+I32+I33 | ... Q34: =Q30+Q31+Q32+Q33 | T34: =IF(ISBLANK(C34),"",C34) | U34: =IF(ISBLANK(G34),"",G34) | V34: =IF(ISBLANK(K34),"",K34) | W34: =IF(ISBLANK(O34),"",O34) | X34: =IF(ISBLANK(Q34),"",Q34) | AA34: Cash + AR + Inv + OtherCA
A36: PPE (rolled) | B36: 4241.5 | C36: 4440.5 | D36: 4272.4 | E36: 4318.6 | F36: 4397.9 | G36: 4664.6 | H36: 4702 | I36: 4783.3 | J36: =I36-FS!J64-I36*FS!$B$100 | K36: =J36-FS!K64-J36*FS!$B$100 | L36: =K36-FS!L64-K36*FS!$B$100 | M36: =L36-FS!M64-L36*FS!$B$100 | N36: =M36-FS!N64-M36*FS!$B$100 | O36: =N36-FS!O64-N36*FS!$B$100 | P36: =O36-FS!P64-O36*FS!$B$100 | Q36: =P36-FS!Q64-P36*FS!$B$100 | T36: =IF(ISBLANK(C36),"",C36) | U36: =IF(ISBLANK(G36),"",G36) | V36: =IF(ISBLANK(K36),"",K36) | W36: =IF(ISBLANK(O36),"",O36) | X36: =IF(ISBLANK(Q36),"",Q36) | AA36: Prior PPE + Capex − D&A (Prior PPE × 4.39%/Q (calibrated to the disclosed guide 210億/Q at the latest PPE; rises with PPE thereafter))
A37: Other NCA | B37: =B38-B34-B36 | C37: =C38-C34-C36 | D37: =D38-D34-D36 | E37: =E38-E34-E36 | F37: =F38-F34-F36 | G37: =G38-G34-G36 | H37: =H38-H34-H36 | I37: =I38-I34-I36 | J37: =I37 | K37: =J37 | L37: =K37 | M37: =L37 | N37: =M37 | O37: =N37 | P37: =O37 | Q37: =P37 | T37: =IF(ISBLANK(C37),"",C37) | U37: =IF(ISBLANK(G37),"",G37) | V37: =IF(ISBLANK(K37),"",K37) | W37: =IF(ISBLANK(O37),"",O37) | X37: =IF(ISBLANK(Q37),"",Q37) | AA37: Held constant from prior
A38: TOTAL ASSETS | B38: 12713.6 | C38: 13411.2 | D38: 12902.4 | E38: 13529.8 | F38: 14172.1 | G38: 14599.3 | H38: 14906 | I38: 15121.6 | J38: =J34+J36+J37 | K38: =K34+K36+K37 | L38: =L34+L36+L37 | M38: =M34+M36+M37 | N38: =N34+N36+N37 | O38: =O34+O36+O37 | P38: =P34+P36+P37 | Q38: =Q34+Q36+Q37 | T38: =IF(ISBLANK(C38),"",C38) | U38: =IF(ISBLANK(G38),"",G38) | V38: =IF(ISBLANK(K38),"",K38) | W38: =IF(ISBLANK(O38),"",O38) | X38: =IF(ISBLANK(Q38),"",Q38) | Y38: =Q38 | AA38: CA + PPE + OtherNCA
A40: Trade Payables | B40: 1597.5 | C40: 1865.9 | D40: 1682.4 | E40: 1618.1 | F40: 1582.8 | G40: 1810.5 | H40: 1706.5 | I40: 1805.4 | J40: =J57*FS!J5/91 | K40: =K57*FS!K5/91 | L40: =L57*FS!L5/91 | M40: =M57*FS!M5/91 | N40: =N57*FS!N5/91 | O40: =O57*FS!O5/91 | P40: =P57*FS!P5/91 | Q40: =Q57*FS!Q5/91 | T40: =IF(ISBLANK(C40),"",C40) | U40: =IF(ISBLANK(G40),"",G40) | V40: =IF(ISBLANK(K40),"",K40) | W40: =IF(ISBLANK(O40),"",O40) | X40: =IF(ISBLANK(Q40),"",Q40) | AA40: COGS × DPO / 91 (or actual)
A41: Debt | B41: 2510.4 | C41: 2524.4 | D41: 2620.2 | E41: 3268.8 | F41: 3560.7 | G41: 3220.5 | H41: 3556.6 | I41: 3477.8 | J41: =I41+FS!J77 | K41: =J41+FS!K77 | L41: =K41+FS!L77 | M41: =L41+FS!M77 | N41: =M41+FS!N77 | O41: =N41+FS!O77 | P41: =O41+FS!P77 | Q41: =P41+FS!Q77 | T41: =IF(ISBLANK(C41),"",C41) | U41: =IF(ISBLANK(G41),"",G41) | V41: =IF(ISBLANK(K41),"",K41) | W41: =IF(ISBLANK(O41),"",O41) | X41: =IF(ISBLANK(Q41),"",Q41) | AA41: Prior Debt + Net Debt Issuance (held flat unless a schedule is set)
A42: Other Liab | B42: =B43-B40-B41 | C42: =C43-C40-C41 | D42: =D43-D40-D41 | E42: =E43-E40-E41 | F42: =F43-F40-F41 | G42: =G43-G40-G41 | H42: =H43-H40-H41 | I42: =I43-I40-I41 | J42: =I42 | K42: =J42 | L42: =K42 | M42: =L42 | N42: =M42 | O42: =N42 | P42: =O42 | Q42: =P42 | T42: =IF(ISBLANK(C42),"",C42) | U42: =IF(ISBLANK(G42),"",G42) | V42: =IF(ISBLANK(K42),"",K42) | W42: =IF(ISBLANK(O42),"",O42) | X42: =IF(ISBLANK(Q42),"",Q42) | AA42: Held constant from prior (roll-forward)
A43: TOTAL LIAB | B43: 6341.8 | C43: 6653.1 | D43: 6408.3 | E43: 6937.2 | F43: 7359.2 | G43: 7236.2 | H43: 7434.6 | I43: 7374.1 | J43: =J40+J41+J42 | K43: =K40+K41+K42 | L43: =L40+L41+L42 | M43: =M40+M41+M42 | N43: =N40+N41+N42 | O43: =O40+O41+O42 | P43: =P40+P41+P42 | Q43: =Q40+Q41+Q42 | T43: =IF(ISBLANK(C43),"",C43) | U43: =IF(ISBLANK(G43),"",G43) | V43: =IF(ISBLANK(K43),"",K43) | W43: =IF(ISBLANK(O43),"",O43) | X43: =IF(ISBLANK(Q43),"",Q43) | AA43: AP + Debt + OtherL (independent components)
A45: Shareholders Eq | B45: 6191.5 | C45: 6558.1 | D45: 6309.3 | E45: 6413.1 | F45: 6618.4 | G45: 7153.7 | H45: 7259.2 | I45: 7545.7 | J45: =I45+FS!J18-FS!J23*FS!J21/100-FS!J76 | K45: =J45+FS!K18-FS!K23*FS!K21/100-FS!K76 | L45: =K45+FS!L18-FS!L23*FS!L21/100-FS!L76 | M45: =L45+FS!M18-FS!M23*FS!M21/100-FS!M76 | N45: =M45+FS!N18-FS!N23*FS!N21/100-FS!N76 | O45: =N45+FS!O18-FS!O23*FS!O21/100-FS!O76 | P45: =O45+FS!P18-FS!P23*FS!P21/100-FS!P76 | Q45: =P45+FS!Q18-FS!Q23*FS!Q21/100-FS!Q76 | T45: =IF(ISBLANK(C45),"",C45) | U45: =IF(ISBLANK(G45),"",G45) | V45: =IF(ISBLANK(K45),"",K45) | W45: =IF(ISBLANK(O45),"",O45) | X45: =IF(ISBLANK(Q45),"",Q45) | Y45: =Q45 | AA45: Prior Eq + NI − Dividends − Buyback
A46: Retained Earnings | B46: 5052.4 | C46: 5208.1 | D46: 5169.9 | E46: 5261 | F46: 5286.3 | G46: 5559.9 | H46: 5535.9 | I46: 5710.8 | J46: =I46+FS!J18-FS!J75-FS!J76 | K46: =J46+FS!K18-FS!K75-FS!K76 | L46: =K46+FS!L18-FS!L75-FS!L76 | M46: =L46+FS!M18-FS!M75-FS!M76 | N46: =M46+FS!N18-FS!N75-FS!N76 | O46: =N46+FS!O18-FS!O75-FS!O76 | P46: =O46+FS!P18-FS!P75-FS!P76 | Q46: =P46+FS!Q18-FS!Q75-FS!Q76 | T46: =IF(ISBLANK(C46),"",C46) | U46: =IF(ISBLANK(G46),"",G46) | V46: =IF(ISBLANK(K46),"",K46) | W46: =IF(ISBLANK(O46),"",O46) | X46: =IF(ISBLANK(Q46),"",Q46) | AA46: Prior RE + NI − Dividends − Buyback
A47: Non-controlling | B47: 180.3 | C47: 200 | D47: 184.9 | E47: 179.5 | F47: 194.5 | G47: 209.4 | H47: 212.1 | I47: 201.8 | J47: =I47 | K47: =J47 | L47: =K47 | M47: =L47 | N47: =M47 | O47: =N47 | P47: =O47 | Q47: =P47 | T47: =IF(ISBLANK(C47),"",C47) | U47: =IF(ISBLANK(G47),"",G47) | V47: =IF(ISBLANK(K47),"",K47) | W47: =IF(ISBLANK(O47),"",O47) | X47: =IF(ISBLANK(Q47),"",Q47) | AA47: Held constant from prior (roll-forward, NOT zeroed)
A48: TOTAL EQUITY | B48: =B45+B47 | C48: =C45+C47 | D48: =D45+D47 | E48: =E45+E47 | F48: =F45+F47 | G48: =G45+G47 | H48: =H45+H47 | I48: =I45+I47 | ... Q48: =Q45+Q47 | T48: =IF(ISBLANK(C48),"",C48) | U48: =IF(ISBLANK(G48),"",G48) | V48: =IF(ISBLANK(K48),"",K48) | W48: =IF(ISBLANK(O48),"",O48) | X48: =IF(ISBLANK(Q48),"",Q48) | AA48: Eq + NCI
A50: BS Check (TA-TL-TE) | B50: =B38-B43-B48 | C50: =C38-C43-C48 | D50: =D38-D43-D48 | E50: =E38-E43-E48 | F50: =F38-F43-F48 | G50: =G38-G43-G48 | H50: =H38-H43-H48 | I50: =I38-I43-I48 | ... Q50: =Q38-Q43-Q48 | AA50: TA − TL − TE (must = 0; non-zero ⇒ roll-forward inconsistency)
...

Sheet Valuation
A1: Sumitomo Rubber Industries Valuation — LEFT=DCF/PE/PB + verdict; RIGHT=5y multiples history
A2: BLUE=input, BLACK=formula, GREEN=cross-sheet
A3: Method 1: DCF (FCFF, equity-only) | F3: MULTIPLES HISTORY (5y, split-adjusted)
A4: FY+1 FCF (億, OCF+ICF) | B4: =IFERROR((FS!H63+FS!I63+FS!J63+FS!K63)+(FS!H64+FS!I64+FS!J64+FS!K64),"") | F4: Stat | G4: P/E | H4: P/B
A5: FCF growth Y2-Y5 % | B5: 5 | F5: Mean | G5: 17.46 | H5: 0.69
A6: Terminal growth % | B6: 2 | F6: Median | G6: 12.04 | H6: 0.69
A7: Rf % (10y JGB) | B7: 1.5 | F7: StdDev | G7: 18.17 | H7: 0.11
A8: ERP % (JP equity premium) | B8: 5 | F8: Mean +1SD | G8: 35.62 | H8: 0.8
A9: Beta (5y vs TOPIX) | B9: 1.074 | F9: Mean −1SD | G9: -0.71 | H9: 0.58
A10: WACC % = Rf + β × ERP | B10: =B7+B9*B8 | F10: CURRENT | G10: 8.58 | H10: 0.7
A11: Stub: days to FY end ÷ 365.25 | B11: =(DATE(YEAR(TODAY())+IF(MONTH(TODAY())>12,1,0),12+1,0)-TODAY())/365.25 | F11: Pct Rank % | G11: 22.47 | H11: 56.72
A12: Mid-year convention: Y1 discount=stub/2, Yn≥2 = stub + (n-1) - 0.5
A13: Y1 | B13: =B4 | C13: =1/(1+$B$10/100)^($B$11/2) | D13: =B13*C13 | F13: Current Price (¥) | G13: 2020
A14: Y2 | B14: =B13*(1+$B$5/100) | C14: =1/(1+$B$10/100)^($B$11+2-1-0.5) | D14: =B14*C14 | F14: Current TTM EPS (¥) | G14: 235.39
A15: Y3 | B15: =B14*(1+$B$5/100) | C15: =1/(1+$B$10/100)^($B$11+3-1-0.5) | D15: =B15*C15 | F15: Current BPS (¥) | G15: 2869.5
A16: Y4 | B16: =B15*(1+$B$5/100) | C16: =1/(1+$B$10/100)^($B$11+4-1-0.5) | D16: =B16*C16
A17: Y5 | B17: =B16*(1+$B$5/100) | C17: =1/(1+$B$10/100)^($B$11+5-1-0.5) | D17: =B17*C17 | F17: Recent 30 days
F18: Date | G18: Close | H18: TTM EPS | I18: BPS | J18: P/E | K18: P/B
A19: Terminal (discounted at end-of-Y5 = stub + 4.5) | B19: =B17*(1+$B$6/100)/(($B$10-$B$6)/100) | C19: =1/(1+$B$10/100)^($B$11+4.5) | D19: =B19*C19 | F19: 2026-08-13 | G19: 2377 | H19: 235.39 | I19: 2869.5 | J19: 10.1 | K19: 0.83
F20: 2026-08-14 | G20: 2397 | H20: 235.39 | I20: 2869.5 | J20: 10.19 | K20: 0.84
A21: Enterprise Value (億) | B21: =SUM(D13:D17)+D19 | F21: 2026-08-17 | G21: 2360 | H21: 235.39 | I21: 2869.5 | J21: 10.03 | K21: 0.82
A22: Net Cash = Cash − Debt (FY26Q2 actual) | B22: =FS!I30-FS!I41 | F22: 2026-08-18 | G22: 2311 | H22: 235.39 | I22: 2869.5 | J22: 9.82 | K22: 0.81
A23: Equity Value (億) | B23: =B21+B22 | F23: 2026-08-19 | G23: 2243 | H23: 235.39 | I23: 2869.5 | J23: 9.53 | K23: 0.78
A24: Shares (M) | B24: 262.9 | F24: 2026-08-20 | G24: 2296 | H24: 235.39 | I24: 2869.5 | J24: 9.75 | K24: 0.8
A25: DCF implied price (¥) | B25: =B23*100/B24 | F25: 2026-08-21 | G25: 2297 | H25: 235.39 | I25: 2869.5 | J25: 9.76 | K25: 0.8
A26: Net Cash floor (¥) | B26: =B22*100/B24 | F26: 2026-08-24 | G26: 2325 | H26: 235.39 | I26: 2869.5 | J26: 9.88 | K26: 0.81
F27: 2026-08-25 | G27: 2290 | H27: 235.39 | I27: 2869.5 | J27: 9.73 | K27: 0.8
A28: Method 2: P/E range (NTM blend) | F28: 2026-08-26 | G28: 2302 | H28: 235.39 | I28: 2869.5 | J28: 9.78 | K28: 0.8
A29: Blend weight on FY+1 (auto = days→FY end / 365) | B29: =MAX(0,MIN(1,1-(TODAY()-DATE(YEAR(TODAY())-IF(MONTH(TODAY())>12,0,1),12+1,0))/365.25)) | F29: 2026-08-27 | G29: 2243 | H29: 235.39 | I29: 2869.5 | J29: 9.53 | K29: 0.78
A30: FY+1 EPS forecast (¥, sum of 4Q) | B30: =FS!H22+FS!I22+FS!J22+FS!K22 | F30: 2026-08-28 | G30: 2223 | H30: 235.39 | I30: 2869.5 | J30: 9.45 | K30: 0.77
A31: FY+2 EPS forecast (¥, sum of 4Q) | B31: =FS!L22+FS!M22+FS!N22+FS!O22 | F31: 2026-08-31 | G31: 2245 | H31: 235.39 | I31: 2869.5 | J31: 9.54 | K31: 0.78
A32: NTM EPS = w·FY+1 + (1−w)·FY+2 | B32: =B29*B30+(1-B29)*B31 | F32: 2026-09-01 | G32: 2292 | H32: 235.39 | I32: 2869.5 | J32: 9.74 | K32: 0.8
A33: 5y mean P/E | B33: =Valuation!G5 | F33: 2026-09-02 | G33: 2160 | H33: 235.39 | I33: 2869.5 | J33: 9.18 | K33: 0.75
A34: 5y +1SD P/E | B34: =Valuation!G8 | F34: 2026-09-03 | G34: 2168 | H34: 235.39 | I34: 2869.5 | J34: 9.21 | K34: 0.76
A35: 5y −1SD P/E | B35: =Valuation!G9 | F35: 2026-09-04 | G35: 2099 | H35: 235.39 | I35: 2869.5 | J35: 8.92 | K35: 0.73
A36: Implied @mean (NTM) | B36: =B32*B33 | F36: 2026-09-07 | G36: 2085 | H36: 235.39 | I36: 2869.5 | J36: 8.86 | K36: 0.73
A37: Implied @+1SD | B37: =B32*B34 | F37: 2026-09-08 | G37: 1985 | H37: 235.39 | I37: 2869.5 | J37: 8.43 | K37: 0.69
A38: Implied @−1SD | B38: =B32*B35 | F38: 2026-09-09 | G38: 2027 | H38: 235.39 | I38: 2869.5 | J38: 8.61 | K38: 0.71
F39: 2026-09-10 | G39: 2004 | H39: 235.39 | I39: 2869.5 | J39: 8.51 | K39: 0.7
F40: 2026-09-11 | G40: 1996 | H40: 235.39 | I40: 2869.5 | J40: 8.48 | K40: 0.7
...

Sheet Industry
A1: Industry / Macro Indicators — context for Sumitomo Rubber Industries (¥億, monthly)
A2: Rows = indicators; Cols = months (latest right). Easy to plot. Sources: JMTBA + MOF 貿易統計
A4: Indicator | B4: 202408 | C4: 202409 | D4: 202410 | E4: 202411 | F4: 202412 | G4: 202501 | H4: 202502 | I4: 202503 | J4: 202504 | K4: 202505 | L4: 202506 | M4: 202507 | N4: 202508 | O4: 202509 | P4: 202510 | Q4: 202511 | R4: 202512 | S4: 202601 | T4: 202602 | U4: 202603 | V4: 202604 | W4: 202605 | X4: 202606 | Y4: 202607 | Z4: 202608
A5: JMTBA total (億) | B5: 1107.7 | C5: 1253.6 | D5: 1225.5 | E5: 1193.3 | F5: 1430.9 | G5: 1161.5 | H5: 1182 | I5: 1511 | J5: 1302.1 | K5: 1287.2 | L5: 1331.6 | M5: 1283.6 | N5: 1201.7 | O5: 1391.5 | P5: 1434.6 | Q5: 1370 | R5: 1586.4 | S5: 1455.8 | T5: 1467.4 | U5: 1934.7 | V5: 1889.7 | W5: 1770.1 | X5: 2033.8 | Y5: 1930.9
A6: total YoY % | N6: =IFERROR(N5/B5-1,"") | O6: =IFERROR(O5/C5-1,"") | P6: =IFERROR(P5/D5-1,"") | Q6: =IFERROR(Q5/E5-1,"") | R6: =IFERROR(R5/F5-1,"") | S6: =IFERROR(S5/G5-1,"") | T6: =IFERROR(T5/H5-1,"") | U6: =IFERROR(U5/I5-1,"") | ... Z6: =IFERROR(Z5/N5-1,"")
A7: JMTBA domestic (億) | B7: 321.9 | C7: 415.3 | D7: 334.4 | E7: 343.3 | F7: 399.2 | G7: 320 | H7: 337.7 | I7: 492.6 | J7: 343.8 | K7: 330.2 | L7: 398.7 | M7: 354.5 | N7: 318.9 | O7: 436.4 | P7: 356.9 | Q7: 319.9 | R7: 399.1 | S7: 326.2 | T7: 371.6 | U7: 504.7 | V7: 492.9 | W7: 453.3 | X7: 580.2 | Y7: 532.4
A8: domestic YoY % | N8: =IFERROR(N7/B7-1,"") | O8: =IFERROR(O7/C7-1,"") | P8: =IFERROR(P7/D7-1,"") | Q8: =IFERROR(Q7/E7-1,"") | R8: =IFERROR(R7/F7-1,"") | S8: =IFERROR(S7/G7-1,"") | T8: =IFERROR(T7/H7-1,"") | U8: =IFERROR(U7/I7-1,"") | ... Z8: =IFERROR(Z7/N7-1,"")
A9: JMTBA foreign (億) | B9: 785.8 | C9: 838.3 | D9: 891.1 | E9: 850 | F9: 1031.7 | G9: 841.5 | H9: 844.3 | I9: 1018.4 | J9: 958.4 | K9: 957 | L9: 932.9 | M9: 929.1 | N9: 882.8 | O9: 955 | P9: 1077.6 | Q9: 1050.2 | R9: 1187.4 | S9: 1129.5 | T9: 1095.8 | U9: 1430 | V9: 1396.8 | W9: 1316.8 | X9: 1453.5 | Y9: 1398.5
A10: foreign YoY % | N10: =IFERROR(N9/B9-1,"") | O10: =IFERROR(O9/C9-1,"") | P10: =IFERROR(P9/D9-1,"") | Q10: =IFERROR(Q9/E9-1,"") | R10: =IFERROR(R9/F9-1,"") | S10: =IFERROR(S9/G9-1,"") | T10: =IFERROR(T9/H9-1,"") | U10: =IFERROR(U9/I9-1,"") | ... Z10: =IFERROR(Z9/N9-1,"")
A11: JMTBA backlog (億) | B11: 8005.3 | C11: 7677.2 | D11: 7751.9 | E11: 7700 | F11: 7678.2 | G11: 7726.6 | H11: 7599.4 | I11: 6924 | J11: 6957.6 | K11: 7131.3 | L11: 7175.2 | M11: 7251 | N11: 7292 | O11: 7329.6 | P11: 7564.8 | Q11: 7594.8 | R11: 7574.3 | S11: 7750.9 | T11: 8026.2 | U11: 8116.1 | V11: 8782.5 | W11: 9282.2 | X11: 9665 | Y11: 10091.4
A12: backlog YoY % | N12: =IFERROR(N11/B11-1,"") | O12: =IFERROR(O11/C11-1,"") | P12: =IFERROR(P11/D11-1,"") | Q12: =IFERROR(Q11/E11-1,"") | R12: =IFERROR(R11/F11-1,"") | S12: =IFERROR(S11/G11-1,"") | T12: =IFERROR(T11/H11-1,"") | U12: =IFERROR(U11/I11-1,"") | ... Z12: =IFERROR(Z11/N11-1,"")
A14: JMTBA total 速報 (億) | U14: 1935.1 | V14: 1889.7 | W14: 1768.3 | X14: 2035.2 | Y14: 1931 | Z14: 1978.8
A15: total 速報 YoY % | N15: =IFERROR(N14/B14-1,"") | O15: =IFERROR(O14/C14-1,"") | P15: =IFERROR(P14/D14-1,"") | Q15: =IFERROR(Q14/E14-1,"") | R15: =IFERROR(R14/F14-1,"") | S15: =IFERROR(S14/G14-1,"") | T15: =IFERROR(T14/H14-1,"") | U15: =IFERROR(U14/I14-1,"") | ... Z15: =IFERROR(Z14/N14-1,"")
A16: JMTBA domestic 速報 (億) | U16: 505.1 | V16: 492.9 | W16: 450.4 | X16: 580.2 | Y16: 532.4 | Z16: 515.3
A17: domestic 速報 YoY % | N17: =IFERROR(N16/B16-1,"") | O17: =IFERROR(O16/C16-1,"") | P17: =IFERROR(P16/D16-1,"") | Q17: =IFERROR(Q16/E16-1,"") | R17: =IFERROR(R16/F16-1,"") | S17: =IFERROR(S16/G16-1,"") | T17: =IFERROR(T16/H16-1,"") | U17: =IFERROR(U16/I16-1,"") | ... Z17: =IFERROR(Z16/N16-1,"")
A18: JMTBA foreign 速報 (億) | U18: 1430 | V18: 1396.8 | W18: 1318 | X18: 1455 | Y18: 1398.6 | Z18: 1463.5
A19: foreign 速報 YoY % | N19: =IFERROR(N18/B18-1,"") | O19: =IFERROR(O18/C18-1,"") | P19: =IFERROR(P18/D18-1,"") | Q19: =IFERROR(Q18/E18-1,"") | R19: =IFERROR(R18/F18-1,"") | S19: =IFERROR(S18/G18-1,"") | T19: =IFERROR(T18/H18-1,"") | U19: =IFERROR(U18/I18-1,"") | ... Z19: =IFERROR(Z18/N18-1,"")
A21: JMTBA 中国 (億) | B21: 285.3 | C21: 274.2 | D21: 290 | E21: 293.2 | F21: 362.5 | G21: 276 | H21: 266.8 | I21: 360.9 | J21: 339.8 | K21: 309.5 | L21: 321.8 | M21: 319.5 | N21: 293.2 | O21: 342.8 | P21: 317.9 | Q21: 381.3 | R21: 371.2 | S21: 433 | T21: 374.6 | U21: 513.5 | V21: 533.3 | W21: 512.5 | X21: 564.9 | Y21: 486.3
A22: 中国 YoY % | N22: =IFERROR(N21/B21-1,"") | O22: =IFERROR(O21/C21-1,"") | P22: =IFERROR(P21/D21-1,"") | Q22: =IFERROR(Q21/E21-1,"") | R22: =IFERROR(R21/F21-1,"") | S22: =IFERROR(S21/G21-1,"") | T22: =IFERROR(T21/H21-1,"") | U22: =IFERROR(U21/I21-1,"") | ... Z22: =IFERROR(Z21/N21-1,"")
A23: JMTBA アメリカ (億) | B23: 205.1 | C23: 221.6 | D23: 174.2 | E23: 235.8 | F23: 289.4 | G23: 207.7 | H23: 230.3 | I23: 247 | J23: 272.3 | K23: 289.9 | L23: 249.3 | M23: 237.9 | N23: 240.8 | O23: 259 | P23: 282.9 | Q23: 263.9 | R23: 345.8 | S23: 310.9 | T23: 312.1 | U23: 392.6 | V23: 358.1 | W23: 303.5 | X23: 360 | Y23: 371.1
A24: アメリカ YoY % | N24: =IFERROR(N23/B23-1,"") | O24: =IFERROR(O23/C23-1,"") | P24: =IFERROR(P23/D23-1,"") | Q24: =IFERROR(Q23/E23-1,"") | R24: =IFERROR(R23/F23-1,"") | S24: =IFERROR(S23/G23-1,"") | T24: =IFERROR(T23/H23-1,"") | U24: =IFERROR(U23/I23-1,"") | ... Z24: =IFERROR(Z23/N23-1,"")
A25: JMTBA インド (億) | B25: 52.7 | C25: 55.3 | D25: 97.1 | E25: 55.6 | F25: 50.6 | G25: 83.9 | H25: 53.9 | I25: 98.2 | J25: 47.4 | K25: 45.3 | L25: 51.4 | M25: 61.1 | N25: 49.8 | O25: 53.2 | P25: 49 | Q25: 59 | R25: 63.9 | S25: 58.4 | T25: 78.8 | U25: 116.6 | V25: 76.6 | W25: 57.7 | X25: 91.6 | Y25: 72.8
A26: インド YoY % | N26: =IFERROR(N25/B25-1,"") | O26: =IFERROR(O25/C25-1,"") | P26: =IFERROR(P25/D25-1,"") | Q26: =IFERROR(Q25/E25-1,"") | R26: =IFERROR(R25/F25-1,"") | S26: =IFERROR(S25/G25-1,"") | T26: =IFERROR(T25/H25-1,"") | U26: =IFERROR(U25/I25-1,"") | ... Z26: =IFERROR(Z25/N25-1,"")
A27: JMTBA 台湾 (億) | B27: 11.3 | C27: 23.2 | D27: 16.8 | E27: 10.3 | F27: 16.4 | G27: 12.8 | H27: 16.8 | I27: 21.8 | J27: 18.2 | K27: 16.2 | L27: 12.7 | M27: 15.5 | N27: 11.2 | O27: 14.9 | P27: 21.4 | Q27: 18.1 | R27: 13.3 | S27: 33.6 | T27: 19 | U27: 22 | V27: 33.8 | W27: 49.4 | X27: 35.8 | Y27: 40.5
A28: 台湾 YoY % | N28: =IFERROR(N27/B27-1,"") | O28: =IFERROR(O27/C27-1,"") | P28: =IFERROR(P27/D27-1,"") | Q28: =IFERROR(Q27/E27-1,"") | R28: =IFERROR(R27/F27-1,"") | S28: =IFERROR(S27/G27-1,"") | T28: =IFERROR(T27/H27-1,"") | U28: =IFERROR(U27/I27-1,"") | ... Z28: =IFERROR(Z27/N27-1,"")
A29: JMTBA 韓国 (億) | B29: 38.3 | C29: 20.4 | D29: 28.4 | E29: 15.1 | F29: 24 | G29: 26.3 | H29: 30.4 | I29: 25.9 | J29: 32.4 | K29: 24 | L29: 19.4 | M29: 18.4 | N29: 20.9 | O29: 25.3 | P29: 43.1 | Q29: 28.4 | R29: 19.2 | S29: 28.4 | T29: 30 | U29: 26.6 | V29: 37.5 | W29: 19.8 | X29: 33.5 | Y29: 50
A30: 韓国 YoY % | N30: =IFERROR(N29/B29-1,"") | O30: =IFERROR(O29/C29-1,"") | P30: =IFERROR(P29/D29-1,"") | Q30: =IFERROR(Q29/E29-1,"") | R30: =IFERROR(R29/F29-1,"") | S30: =IFERROR(S29/G29-1,"") | T30: =IFERROR(T29/H29-1,"") | U30: =IFERROR(U29/I29-1,"") | ... Z30: =IFERROR(Z29/N29-1,"")
A31: JMTBA ドイツ (億) | B31: 25.3 | C31: 35.8 | D31: 26.1 | E31: 27.8 | F31: 29.1 | G31: 30.4 | H31: 37.9 | I31: 34.8 | J31: 33.8 | K31: 36.3 | L31: 35.5 | M31: 34.4 | N31: 27.2 | O31: 36 | P31: 43 | Q31: 41.6 | R31: 42.8 | S31: 38.1 | T31: 39.5 | U31: 42.9 | V31: 44.7 | W31: 32.2 | X31: 32.6 | Y31: 46.8
A32: ドイツ YoY % | N32: =IFERROR(N31/B31-1,"") | O32: =IFERROR(O31/C31-1,"") | P32: =IFERROR(P31/D31-1,"") | Q32: =IFERROR(Q31/E31-1,"") | R32: =IFERROR(R31/F31-1,"") | S32: =IFERROR(S31/G31-1,"") | T32: =IFERROR(T31/H31-1,"") | U32: =IFERROR(U31/I31-1,"") | ... Z32: =IFERROR(Z31/N31-1,"")
A33: JMTBA うち自動車部品 (億) | B33: 50.9 | C33: 54.1 | D33: 44.9 | E33: 35.1 | F33: 52.6 | G33: 36.8 | H33: 53.6 | I33: 71.6 | J33: 32.6 | K33: 34.4 | L33: 43 | M33: 55.2 | N33: 45.6 | O33: 50.8 | P33: 43.4 | Q33: 42.5 | R33: 59.3 | S33: 40.4 | T33: 59.4 | U33: 61.8 | V33: 76.9 | W33: 55.9 | X33: 85.9 | Y33: 72.3
A34: うち自動車部品 YoY % | N34: =IFERROR(N33/B33-1,"") | O34: =IFERROR(O33/C33-1,"") | P34: =IFERROR(P33/D33-1,"") | Q34: =IFERROR(Q33/E33-1,"") | R34: =IFERROR(R33/F33-1,"") | S34: =IFERROR(S33/G33-1,"") | T34: =IFERROR(T33/H33-1,"") | U34: =IFERROR(U33/I33-1,"") | ... Z34: =IFERROR(Z33/N33-1,"")
A35: JMTBA 電気・精密 計 (億) | B35: 26.1 | C35: 59.6 | D35: 42 | E35: 40.6 | F35: 48.5 | G35: 43.3 | H35: 32.4 | I35: 53.4 | J35: 48.3 | K35: 48.2 | L35: 58.6 | M35: 40.3 | N35: 33.3 | O35: 53.7 | P35: 39.6 | Q35: 34.9 | R35: 39.2 | S35: 52.2 | T35: 57.7 | U35: 73.8 | V35: 78 | W35: 51.3 | X35: 97.3 | Y35: 82.2
A36: 電気・精密 計 YoY % | N36: =IFERROR(N35/B35-1,"") | O36: =IFERROR(O35/C35-1,"") | P36: =IFERROR(P35/D35-1,"") | Q36: =IFERROR(Q35/E35-1,"") | R36: =IFERROR(R35/F35-1,"") | S36: =IFERROR(S35/G35-1,"") | T36: =IFERROR(T35/H35-1,"") | U36: =IFERROR(U35/I35-1,"") | ... Z36: =IFERROR(Z35/N35-1,"")
A38: MOF Robot Exp HS 8479 (億) | B38: 819.7 | C38: 831.6 | D38: 852.8 | E38: 781.9 | F38: 988.7 | G38: 666.6 | H38: 877 | I38: 969.1 | J38: 824.4 | K38: 874.8 | L38: 893.6 | M38: 975.8 | N38: 803.5 | O38: 843.7 | P38: 959.1 | Q38: 898.4 | R38: 1061.1 | S38: 849.7 | T38: 849.4 | U38: 1089.9 | V38: 1055.3 | W38: 983.6 | X38: 1015.5 | Y38: 1160.1
A39: MOF Robot Exp HS 8479 YoY % | N39: =IFERROR(N38/B38-1,"") | O39: =IFERROR(O38/C38-1,"") | P39: =IFERROR(P38/D38-1,"") | Q39: =IFERROR(Q38/E38-1,"") | R39: =IFERROR(R38/F38-1,"") | S39: =IFERROR(S38/G38-1,"") | T39: =IFERROR(T38/H38-1,"") | U39: =IFERROR(U38/I38-1,"") | ... Z39: =IFERROR(Z38/N38-1,"")
A40: MOF Semi-Eq Exp HS 8486 (億) | B40: 3429.3 | C40: 3970.3 | D40: 4076 | E40: 3743.4 | F40: 4502.6 | G40: 2879 | H40: 3962.5 | I40: 4984.1 | J40: 3735.3 | K40: 3319.8 | L40: 3877.8 | M40: 3509.4 | N40: 3494.9 | O40: 3844 | P40: 3635.4 | Q40: 3792.2 | R40: 4436.8 | S40: 3156.7 | T40: 3290.9 | U40: 5259 | V40: 3932.1 | W40: 3654.5 | X40: 4601.4 | Y40: 4939.5
A41: MOF Semi-Eq Exp HS 8486 YoY % | N41: =IFERROR(N40/B40-1,"") | O41: =IFERROR(O40/C40-1,"") | P41: =IFERROR(P40/D40-1,"") | Q41: =IFERROR(Q40/E40-1,"") | R41: =IFERROR(R40/F40-1,"") | S41: =IFERROR(S40/G40-1,"") | T41: =IFERROR(T40/H40-1,"") | U41: =IFERROR(U40/I40-1,"") | ... Z41: =IFERROR(Z40/N40-1,"")
A42: MOF CNC Tool Exp HS 8459 (億) | B42: 12.3 | C42: 13.4 | D42: 7.1 | E42: 15.9 | F42: 15.3 | G42: 8.8 | H42: 18.3 | I42: 13.6 | J42: 9.9 | K42: 5.1 | L42: 11.3 | M42: 20.8 | N42: 10.4 | O42: 11.6 | P42: 7.2 | Q42: 4.6 | R42: 14.1 | S42: 5.5 | T42: 8.9 | U42: 11.4 | V42: 13.3 | W42: 9.7 | X42: 9.5 | Y42: 7.2
A43: MOF CNC Tool Exp HS 8459 YoY % | N43: =IFERROR(N42/B42-1,"") | O43: =IFERROR(O42/C42-1,"") | P43: =IFERROR(P42/D42-1,"") | Q43: =IFERROR(Q42/E42-1,"") | R43: =IFERROR(R42/F42-1,"") | S43: =IFERROR(S42/G42-1,"") | T43: =IFERROR(T42/H42-1,"") | U43: =IFERROR(U42/I42-1,"") | ... Z43: =IFERROR(Z42/N42-1,"")

Sheet Comp
A1: Peer Comparables for Sumitomo Rubber Industries (51100) — common multiples
A2: Source: J-Quants daily_bars × fins_summary FY (split-adjusted BPS). P/E(fwd) = Nikkei QUICK consensus for the CURRENT FY — near a company's FY-end that is nearly trailing.
A4: Code | B4: Name | C4: Period | D4: Price | E4: MCap (億) | F4: Sales | G4: OP | H4: NP | I4: EPS | J4: BPS | K4: P/E (fwd) | L4: P/B | M4: OPM % | N4: ROE % | O4: Sales YoY %
A5: 51100 | B5: 住友ゴム工業 | C5: Consensus 2026/12連I予 (n=9) | D5: 2020 | E5: 5311 | F5: 12950 | G5: 901 | H5: 576 | I5: 219.22 | J5: 2724.4 | K5: 9.2 | L5: 0.74 | M5: 7 | N5: 7.8 | O5: 7.3
A6: 51080 | B6: ブリヂストン | C6: Consensus 2026/12連I予 (n=11) | D6: 3832 | E6: 50978 | F6: 46726 | G6: 5128 | H6: 3557 | I6: 288.22 | J6: 2868.5 | K6: 13.3 | L6: 1.34 | M6: 11 | N6: 9.6 | O6: 5.5
A7: 51010 | B7: 横浜ゴム | C7: Consensus 2026/12連I予 (n=8) | D7: 6827 | E7: 10763 | F7: 13410 | G7: 2106 | H7: 1334 | I7: 845.96 | J7: 6536.7 | K7: 8.1 | L7: 1.04 | M7: 15.7 | N7: 12.8 | O7: 8.6
A8: 51050 | B8: ＴＯＹＯ ＴＩＲＥ | C8: Consensus 2026/12連予 (n=8) | D8: 3900 | E8: 6006 | F8: 6273 | G8: 917 | H8: 655 | I8: 531.6 | J8: 3394 | K8: 7.3 | L8: 1.15 | M8: 14.6 | N8: 12.5 | O8: 5.4
A10: MEDIAN (peers) | K10: 8.1 | L10: 1.15 | M10: 14.6 | N10: 12.5 | O10: 5.5

Sheet Summary
A1: Sumitomo Rubber Industries (51100) — Model Summary [BLUE=input, BLACK=formula, GREEN=cross-sheet, YELLOW=key tunable]
A3: Metric | B3: Hist FY25 | C3: Model FY26E | D3: Model FY27E | E3: Company Guide | F3: vs Guide %
A4: Sales (億) | B4: =FS!D4+FS!E4+FS!F4+FS!G4 | C4: =FS!H4+FS!I4+FS!J4+FS!K4 | D4: =FS!L4+FS!M4+FS!N4+FS!O4 | E4: 13300 | F4: =C4/E4-1
A5: OP (億) | B5: =FS!D9+FS!E9+FS!F9+FS!G9 | C5: =FS!H9+FS!I9+FS!J9+FS!K9 | D5: =FS!L9+FS!M9+FS!N9+FS!O9 | E5: 890 | F5: =C5/E5-1
A6: OPM % | B6: =B5/B4*100 | C6: =C5/C4*100 | D6: =D5/D4*100 | E6: 6.69 | F6: =C6/E6-1
A7: NP (億) | B7: =FS!D18+FS!E18+FS!F18+FS!G18 | C7: =FS!H18+FS!I18+FS!J18+FS!K18 | D7: =FS!L18+FS!M18+FS!N18+FS!O18 | E7: 550 | F7: =C7/E7-1
A8: EPS (¥) | B8: =FS!D22+FS!E22+FS!F22+FS!G22 | C8: =FS!H22+FS!I22+FS!J22+FS!K22 | D8: =FS!L22+FS!M22+FS!N22+FS!O22 | E8: 209.25 | F8: =C8/E8-1
A12: Daily Snapshot ─ overwritten by modeling.daily_refresh after EOD
A13: Current Price (¥) | C13: from daily_bars latest close
A14: DCF base (¥) | C14: target_prices.db base scenario
A15: DCF bull (¥) | C15: target_prices.db bull scenario
A16: DCF bear (¥) | C16: target_prices.db bear scenario
A17: Composite verdict | C17: Cheap / Fair / Rich vs current
A18: Peer median P/E (x) | C18: Comp sheet median
A19: Last refresh date
A22: Analyst Notes
A23: ⚠DCFはこの銘柄では読まない。Python側のコンソール出力(scenarios.py)はΔWC=0の粗算スカラーで、工作簿のDCF(Valuation!B25)とは別物。ΔWCの扱いだけで−1,968円〜+6,629円まで動く。判断はP/EとP/Bで行う。
A24: ⚠P/Eバンドも当てにならない。5年の平均P/E 17.42・SD 18.15は、FY22(EPS 35.80)とFY24(EPS 37.51)の2回の業績急減が分母を潰した結果で、−1SDが負値になる。中央値12.02を使うか、P/B(平均0.69・SD0.11、現在0.69=50.8パーセンタイル)を主軸にする。
A25: 駆動: OP = 売上 × 四半期OPM。受注開示が無いためサイクルは値上げ×原材料×数量の3点で見る。
A26: FY26下期OPMは会社の下方修正後ガイド（営業利益890億/事業利益960億）に逆算で合わせてある。
A27: FY27の増益ドライバー: 26年下期値上げの通年寄与 / 欧米アクティブトレッド新製品 / Project ARK・タイ新設備のコスト削減 / Tier3ブランドPneumant投入。
A28: 構造要因: 2025-01にGoodyearから欧米豪のDUNLOP商標権を5.26億ドルで取得。欧州は25年3Qに前倒しで黒字化、26年から自社開発品を投入。
A29: リスク: 大和2026-09-08は足元の原材料市況が会社前提を上回るとして通期計画の達成に留保。2026-02-28の米イスラエルによるイラン攻撃以降、原油と海上運賃が上振れ。
A30: 需給: 信用買残が2026-08-07の68万株から09-11に149万株へ2.2倍、貸借倍率7.3→46.6。下落途中の個人逆張りで上値に滞留玉。
A31: セグメントSOTP参照: スポーツ（売上10.4%）にはS33=3350内にpeerが無い。読み替えはミズノ80220（S33=3800）だが、Compの中央値を純タイヤ倍率に保つため除外している。
A32: 株主: 住友電気工業28.87%（支配株主等の開示あり）。Silchester（activist）は10.31%→6.66%へ継続減。

Sheet Debt
A1: Sumitomo Rubber Industries — Debt Schedule + Credit Metrics. Auto-rendered when fins_details has interest-bearing debt.
B2: FY24Q3 | C2: FY24Q4 | D2: FY25Q1 | E2: FY25Q2 | F2: FY25Q3 | G2: FY25Q4 | H2: FY26Q1 | I2: FY26Q2 | J2: FY26Q3 | K2: FY26Q4 | L2: FY27Q1 | M2: FY27Q2 | N2: FY27Q3 | O2: FY27Q4 | P2: FY28Q1 | Q2: FY28Q2
A4: Beginning of Period (BoP) | B4: =FS!B41 | C4: =FS!B41 | D4: =FS!C41 | E4: =FS!D41 | F4: =FS!E41 | G4: =FS!F41 | H4: =FS!G41 | I4: =FS!H41 | J4: =FS!I41 | ... Q4: =FS!P41
A5: + Issuance (CF row 18 if positive) | B5: =MAX(0,B7-B4) | C5: =MAX(0,C7-C4) | D5: =MAX(0,D7-D4) | E5: =MAX(0,E7-E4) | F5: =MAX(0,F7-F4) | G5: =MAX(0,G7-G4) | H5: =MAX(0,H7-H4) | I5: =MAX(0,I7-I4) | ... Q5: =MAX(0,Q7-Q4)
A6: − Repayment (CF row 18 if negative) | B6: =MAX(0,B4-B7) | C6: =MAX(0,C4-C7) | D6: =MAX(0,D4-D7) | E6: =MAX(0,E4-E7) | F6: =MAX(0,F4-F7) | G6: =MAX(0,G4-G7) | H6: =MAX(0,H4-H7) | I6: =MAX(0,I4-I7) | ... Q6: =MAX(0,Q4-Q7)
A7: End of Period (EoP) — links to BS row 15 | B7: =FS!B41 | C7: =FS!C41 | D7: =FS!D41 | E7: =FS!E41 | F7: =FS!F41 | G7: =FS!G41 | H7: =FS!H41 | I7: =FS!I41 | ... Q7: =FS!Q41
A8: Avg balance (BoP+EoP)/2 | B8: =(B4+B7)/2 | C8: =(C4+C7)/2 | D8: =(D4+D7)/2 | E8: =(E4+E7)/2 | F8: =(F4+F7)/2 | G8: =(G4+G7)/2 | H8: =(H4+H7)/2 | I8: =(I4+I7)/2 | ... Q8: =(Q4+Q7)/2
A10: Interest rate (annual %) | B10: 1.5 | C10: (adjust; reflects current avg cost of debt)
A11: Interest expense (Avg × rate ÷ 4) | B11: =B8*$B$10/100/4 | C11: =C8*$B$10/100/4 | D11: =D8*$B$10/100/4 | E11: =E8*$B$10/100/4 | F11: =F8*$B$10/100/4 | G11: =G8*$B$10/100/4 | H11: =H8*$B$10/100/4 | I11: =I8*$B$10/100/4 | ... Q11: =Q8*$B$10/100/4
A12: Disclosed (fins_details, hist FY only) | B12: 117.5 | C12: 72.9 | D12: 109.2 | E12: 188.6 | F12: 214.6 | G12: 228.3 | H12: 50.8 | I12: 61.8
A14: Credit Metrics
A15: Net Debt (Debt - Cash) | B15: =FS!B41-FS!B30 | C15: =FS!C41-FS!C30 | D15: =FS!D41-FS!D30 | E15: =FS!E41-FS!E30 | F15: =FS!F41-FS!F30 | G15: =FS!G41-FS!G30 | H15: =FS!H41-FS!H30 | I15: =FS!I41-FS!I30 | ... Q15: =FS!Q41-FS!Q30
A16: Net Debt / EBITDA (x) | B16: =IFERROR(B15/((FS!B9+FS!B70)*4),0) | C16: =IFERROR(C15/((FS!C9+FS!C70)*4),0) | D16: =IFERROR(D15/((FS!D9+FS!D70)*4),0) | E16: =IFERROR(E15/((FS!E9+FS!E70)*4),0) | F16: =IFERROR(F15/((FS!F9+FS!F70)*4),0) | G16: =IFERROR(G15/((FS!G9+FS!G70)*4),0) | H16: =IFERROR(H15/((FS!H9+FS!H70)*4),0) | I16: =IFERROR(I15/((FS!I9+FS!I70)*4),0) | ... Q16: =IFERROR(Q15/((FS!Q9+FS!Q70)*4),0)
A17: Interest Coverage (EBITDA/Int) | B17: =IFERROR((FS!B9+FS!B70)/B11,"") | C17: =IFERROR((FS!C9+FS!C70)/C11,"") | D17: =IFERROR((FS!D9+FS!D70)/D11,"") | E17: =IFERROR((FS!E9+FS!E70)/E11,"") | F17: =IFERROR((FS!F9+FS!F70)/F11,"") | G17: =IFERROR((FS!G9+FS!G70)/G11,"") | H17: =IFERROR((FS!H9+FS!H70)/H11,"") | I17: =IFERROR((FS!I9+FS!I70)/I11,"") | ... Q17: =IFERROR((FS!Q9+FS!Q70)/Q11,"")
A18: Debt / Equity (x) | B18: =IFERROR(FS!B41/FS!B48,0) | C18: =IFERROR(FS!C41/FS!C48,0) | D18: =IFERROR(FS!D41/FS!D48,0) | E18: =IFERROR(FS!E41/FS!E48,0) | F18: =IFERROR(FS!F41/FS!F48,0) | G18: =IFERROR(FS!G41/FS!G48,0) | H18: =IFERROR(FS!H41/FS!H48,0) | I18: =IFERROR(FS!I41/FS!I48,0) | ... Q18: =IFERROR(FS!Q41/FS!Q48,0)
A19: Debt / Total Cap (%) | B19: =IFERROR(FS!B41/(FS!B41+FS!B48)*100,0) | C19: =IFERROR(FS!C41/(FS!C41+FS!C48)*100,0) | D19: =IFERROR(FS!D41/(FS!D41+FS!D48)*100,0) | E19: =IFERROR(FS!E41/(FS!E41+FS!E48)*100,0) | F19: =IFERROR(FS!F41/(FS!F41+FS!F48)*100,0) | G19: =IFERROR(FS!G41/(FS!G41+FS!G48)*100,0) | H19: =IFERROR(FS!H41/(FS!H41+FS!H48)*100,0) | I19: =IFERROR(FS!I41/(FS!I41+FS!I48)*100,0) | ... Q19: =IFERROR(FS!Q41/(FS!Q41+FS!Q48)*100,0)
A20: Current Ratio (CA/CL) | B20: =IFERROR(FS!B34/(FS!B40+FS!B42),0) | C20: =IFERROR(FS!C34/(FS!C40+FS!C42),0) | D20: =IFERROR(FS!D34/(FS!D40+FS!D42),0) | E20: =IFERROR(FS!E34/(FS!E40+FS!E42),0) | F20: =IFERROR(FS!F34/(FS!F40+FS!F42),0) | G20: =IFERROR(FS!G34/(FS!G40+FS!G42),0) | H20: =IFERROR(FS!H34/(FS!H40+FS!H42),0) | I20: =IFERROR(FS!I34/(FS!I40+FS!I42),0) | ... Q20: =IFERROR(FS!Q34/(FS!Q40+FS!Q42),0)
A21: Quick Ratio (CA-Inv)/CL | B21: =IFERROR((FS!B34-FS!B32)/(FS!B40+FS!B42),0) | C21: =IFERROR((FS!C34-FS!C32)/(FS!C40+FS!C42),0) | D21: =IFERROR((FS!D34-FS!D32)/(FS!D40+FS!D42),0) | E21: =IFERROR((FS!E34-FS!E32)/(FS!E40+FS!E42),0) | F21: =IFERROR((FS!F34-FS!F32)/(FS!F40+FS!F42),0) | G21: =IFERROR((FS!G34-FS!G32)/(FS!G40+FS!G42),0) | H21: =IFERROR((FS!H34-FS!H32)/(FS!H40+FS!H42),0) | I21: =IFERROR((FS!I34-FS!I32)/(FS!I40+FS!I42),0) | ... Q21: =IFERROR((FS!Q34-FS!Q32)/(FS!Q40+FS!Q42),0)

Sheet Customers
A1: Sumitomo Rubber Industries — Revenue by Customer (single-Q, 億円). Source: deck p5 得意先別売上収益 vision-extracted.
A3: No customer observations in decks DB.

Sheet Cycle
A1: Sumitomo Rubber Industries — Cycle Multiple Bands (full history, PIT, split-adjusted)
A2: UPCYCLE → read P/E. BOTTOM → read P/B (trough EPS makes P/E meaningless). Phase clock is DESCRIPTIVE (full-sample OPM median), never a signal.
A4: 0. P/B comparability gate — cash ÷ equity (FY-end)
A5: range 9.1%-16.0%, mean 13.4%, first3→last3 drift +1.3pp → P/B COMPARABLE across time
A7: 1. Full-history band (monthly, TTM basis)
A8: Metric | B8: n | C8: min | D8: p10 | E8: p25 | F8: median | G8: p75 | H8: p90 | I8: max
A9: P/E | B9: 183 | C9: 5.51 | D9: 7.04 | E9: 8.46 | F9: 10.28 | G9: 13.12 | H9: 23.61 | I9: 194.38
A10: P/B | B10: 203 | C10: 0.52 | D10: 0.59 | E10: 0.71 | F10: 1.01 | G10: 1.23 | H10: 1.37 | I10: 1.93
A12: 2. By cycle phase (OPM median split = 7.54%)
A13: Phase | B13: months | C13: OPM med % | D13: P/E p25 | E13: P/E med | F13: P/E p75 | G13: P/B min | H13: P/B p25 | I13: P/B med | J13: P/B p75 | K13: P/B max
A14: 1 Recovery (低OPM・回升) | B14: 36 | C14: 6.4 | D14: 9.4 | E14: 10.7 | F14: 14 | G14: 0.56 | H14: 0.64 | I14: 0.74 | J14: 0.82 | K14: 1.34
A15: 2 Expansion (高OPM・上行) | B15: 57 | C15: 9.3 | D15: 7.9 | E15: 9 | F15: 10.5 | G15: 0.71 | H15: 1.18 | I15: 1.27 | J15: 1.46 | K15: 1.93
A16: 3 Early-down (高OPM・转跌) | B16: 39 | C16: 9.3 | D16: 7.8 | E16: 9.8 | F16: 12.3 | G16: 0.87 | H16: 1.05 | I16: 1.13 | J16: 1.23 | K16: 1.45
A17: 4 Trough (低OPM・下行) | B17: 59 | C17: 2.9 | D17: 10.6 | E17: 13.5 | F17: 33.7 | G17: 0.52 | H17: 0.58 | I17: 0.69 | J17: 0.75 | K17: 1.27
A19: 3. Cycle extremes (±12M local, PIT). 'prov' = inside the last 12M, no right-hand side yet
A20: Event | B20: Date | C20: Price | D20: TTM OP (億) | E20: OPM % | F20: TTM EPS | G20: BPS | H20: P/E | I20: P/B | J20: confirmed
A21: 盈利峰 OP peak | B21: 2010-08 | C21: 762 | D21: 497 | E21: 8.6 | F21: 101 | G21: 703 | H21: 7.6 | I21: 1.08 | J21: yes
A22: 盈利峰 OP peak | B22: 2015-02 | C22: 2068 | D22: 863 | E22: 10.3 | F22: 203 | G22: 1576 | H22: 10.2 | I22: 1.31 | J22: yes
A23: 盈利峰 OP peak | B23: 2018-08 | C23: 1648 | D23: 733 | E23: 8.1 | F23: 190 | G23: 1726 | H23: 8.7 | I23: 0.95 | J23: yes
A24: 盈利峰 OP peak | B24: 2021-08 | C24: 1319 | D24: 703 | E24: 7.9 | F24: 199 | G24: 1856 | H24: 6.6 | I24: 0.71 | J24: yes
A25: 盈利峰 OP peak | B25: 2024-08 | C25: 1487 | D25: 896 | E25: 7.4 | F25: 257 | G25: 2651 | H25: 5.8 | I25: 0.56 | J25: yes
A26: 盈利峰 OP peak | B26: 2026-08 | C26: 2245 | D26: 937 | E26: 7.5 | F26: 235 | G26: 2870 | H26: 9.5 | I26: 0.78 | J26: prov
A28: 盈利谷 OP trough | B28: 2010-02 | C28: 724 | D28: 287 | E28: 5.5 | F28: 35 | G28: 713 | H28: 20.9 | I28: 1.02 | J28: yes
A29: 盈利谷 OP trough | B29: 2011-08 | C29: 962 | D29: 470 | E29: 7.5 | F29: 76 | G29: 723 | H29: 12.7 | I29: 1.33 | J29: yes
A30: 盈利谷 OP trough | B30: 2017-11 | C30: 2040 | D30: 608 | E30: 7.5 | F30: 79 | G30: 1666 | H30: 25.8 | I30: 1.22 | J30: yes
A31: 盈利谷 OP trough | B31: 2020-08 | C31: 1021 | D31: 136 | E31: 1.7 | F31: -14 | G31: 1587 | I31: 0.64 | J31: yes
A32: 盈利谷 OP trough | B32: 2023-05 | C32: 1232 | D32: 86 | E32: 0.8 | F32: 6 | G32: 2114 | H32: 194.4 | I32: 0.58 | J32: yes
A33: 盈利谷 OP trough | B33: 2025-08 | C33: 1740 | D33: -37 | E33: -0.3 | F33: -55 | G33: 2441 | I33: 0.71 | J33: yes
A35: 股价顶 Price top | B35: 2013-04 | C35: 1797 | D35: 697 | E35: 9.8 | F35: 135 | G35: 931 | H35: 13.3 | I35: 1.93 | J35: yes
A36: 股价顶 Price top | B36: 2015-04 | C36: 2221 | D36: 863 | E36: 10.3 | F36: 203 | G36: 1576 | H36: 11 | I36: 1.41 | J36: yes
A37: 股价顶 Price top | B37: 2017-10 | C37: 2144 | D37: 637 | E37: 8.1 | F37: 98 | G37: 1639 | H37: 21.9 | I37: 1.31 | J37: yes
A38: 股价顶 Price top | B38: 2021-06 | C38: 1533 | D38: 515 | E38: 6.3 | F38: 139 | G38: 1802 | H38: 11 | I38: 0.85 | J38: yes
A39: 股价顶 Price top | B39: 2024-04 | C39: 1913 | D39: 645 | E39: 5.5 | F39: 141 | G39: 2373 | H39: 13.6 | I39: 0.81 | J39: yes
A40: 股价顶 Price top | B40: 2026-02 | C40: 2781 | D40: 826 | E40: 6.8 | F40: 192 | G40: 2724 | H40: 14.5 | I40: 1.02 | J40: prov
A42: 股价底 Price bottom | B42: 2009-11 | C42: 679 | D42: 355 | E42: 3.7 | F42: -4 | G42: 672 | I42: 1.01 | J42: yes
A43: 股价底 Price bottom | B43: 2014-03 | C43: 1314 | D43: 771 | E43: 9.9 | F43: 171 | G43: 1257 | H43: 7.7 | I43: 1.05 | J43: yes
A44: 股价底 Price bottom | B44: 2016-06 | C44: 1363 | D44: 786 | E44: 9.3 | F44: 247 | G44: 1559 | H44: 5.5 | I44: 0.87 | J44: yes
A45: 股价底 Price bottom | B45: 2020-07 | C45: 876 | D45: 298 | E45: 3.4 | F45: 22 | G45: 1602 | H45: 39.6 | I45: 0.55 | J45: yes
